Workbook

Sheet Cuotas Semanales
A1: N° | B1: STATTUS | C1: AUTO | D1: CRONOGRAMA | E1: PLACA | F1: CANT. CUOTAS | G1: DNI - CE | H1: # CELULAR | I1: NOMBRES Y APELLIDOS | J1: INICIAL | K1: TIPO | L1: N° CUOTAS PROGRAMADAS | M1: N° CUOTAS ATRASADAS | N1: TOTAL CUOTAS PAGADAS | O1: TOTAL | Q1: CUOTA 1 | T1: CUOTA 2 | X1: CUOTA 3 | AB1: CUOTA 4 | AF1: CUOTA 5 | AJ1: CUOTA 6 | AN1: CUOTA 7 | AR1: CUOTA 8 | AV1: CUOTA 9 | AZ1: CUOTA 10 | BD1: CUOTA 11 | BH1: CUOTA 12 | BL1: CUOTA 13 | BP1: CUOTA 14 | BT1: CUOTA 15 | BX1: CUOTA 16 | CB1: CUOTA 17 | CF1: CUOTA 18 | CJ1: CUOTA 19 | CN1: CUOTA 20 | CR1: CUOTA 21 | CV1: CUOTA 22 | CZ1: CUOTA 23 | DD1: CUOTA 24 | DH1: CUOTA 25 | DL1: CUOTA 26 | DP1: CUOTA 27 | DT1: CUOTA 28 | DX1: CUOTA 29 | EB1: CUOTA 30 | EF1: CUOTA 31 | EJ1: CUOTA 32 | EN1: CUOTA 33 | ER1: CUOTA 34 | EV1: CUOTA 35 | EZ1: CUOTA 36 | FD1: CUOTA 37 | FH1: CUOTA 38 | FL1: CUOTA 39 | FP1: CUOTA 40 | FT1: CUOTA 41 | FX1: CUOTA 42 | GB1: CUOTA 43 | GF1: CUOTA 44 | GJ1: CUOTA 45 | GN1: CUOTA 46 | GR1: CUOTA 47 | GV1: CUOTA 48 | GZ1: CUOTA 49 | HD1: CUOTA 50 | HH1: CUOTA 51 | HL1: CUOTA 52
P2: FECHA | Q2: VIAJES | R2: MONTO | S2: Validación de depósito ✔ | T2: FECHA | U2: VIAJES | V2: MONTO | W2: Validación de depósito ✔ | X2: FECHA | Y2: VIAJES | Z2: MONTO | AA2: Validación de depósito ✔ | AB2: FECHA | AC2: VIAJES | AD2: MONTO | AE2: Validación de depósito ✔ | AF2: FECHA | AG2: VIAJES | AH2: MONTO | AI2: Validación de depósito ✔ | AJ2: FECHA | AK2: VIAJES | AL2: MONTO | AM2: Validación de depósito ✔ | AN2: FECHA | AO2: VIAJES | AP2: MONTO | AQ2: Validación de depósito ✔ | AR2: FECHA | AS2: VIAJES | AT2: MONTO | AU2: Validación de depósito ✔ | AV2: FECHA | AW2: VIAJES | AX2: MONTO | AY2: Validación de depósito ✔ | AZ2: FECHA | BA2: VIAJES | BB2: MONTO | BC2: Validación de depósito ✔ | BD2: FECHA | BE2: VIAJES | BF2: MONTO | BG2: Validación de depósito ✔ | BH2: FECHA | BI2: VIAJES | BJ2: MONTO | BK2: Validación de depósito ✔ | BL2: FECHA | BM2: VIAJES | BN2: MONTO | BO2: Validación de depósito ✔ | BP2: FECHA | BQ2: VIAJES | BR2: MONTO | BS2: Validación de depósito ✔ | BT2: FECHA | BU2: VIAJES | BV2: MONTO | BW2: Validación de depósito ✔ | BX2: FECHA | BY2: VIAJES | BZ2: MONTO | CA2: Validación de depósito ✔ | CB2: FECHA | CC2: VIAJES | CD2: MONTO | CE2: Validación de depósito ✔ | CF2: FECHA | CG2: VIAJES | CH2: MONTO | CI2: Validación de depósito ✔ | CJ2: FECHA | CK2: VIAJES | CL2: MONTO | CM2: Validación de depósito ✔ | CN2: FECHA | CO2: VIAJES | CP2: MONTO | CQ2: Validación de depósito ✔ | CR2: FECHA | CS2: VIAJES | CT2: MONTO | CU2: Validación de depósito ✔ | CV2: FECHA | CW2: VIAJES | CX2: MONTO | CY2: Validación de depósito ✔ | CZ2: FECHA | DA2: VIAJES | DB2: MONTO | DC2: Validación de depósito ✔ | DD2: FECHA | DE2: VIAJES | DF2: MONTO | DG2: Validación de depósito ✔ | DH2: FECHA | DI2: VIAJES | DJ2: MONTO | DK2: Validación de depósito ✔ | DL2: FECHA | DM2: VIAJES | DN2: MONTO | DO2: Validación de depósito ✔ | DP2: FECHA | DQ2: VIAJES | DR2: MONTO | DS2: Validación de depósito ✔ | DT2: FECHA | DU2: VIAJES | DV2: MONTO | DW2: Validación de depósito ✔ | DX2: FECHA | DY2: VIAJES | DZ2: MONTO | EA2: Validación de depósito ✔ | EB2: FECHA | EC2: VIAJES | ED2: MONTO | EE2: Validación de depósito ✔ | EF2: FECHA | EG2: VIAJES | EH2: MONTO | EI2: Validación de depósito ✔ | EJ2: FECHA | EK2: VIAJES | EL2: MONTO | EM2: Validación de depósito ✔ | EN2: FECHA | EO2: VIAJES | EP2: MONTO | EQ2: Validación de depósito ✔ | ER2: FECHA | ES2: VIAJES | ET2: MONTO | EU2: Validación de depósito ✔ | EV2: FECHA | EW2: VIAJES | EX2: MONTO | EY2: Validación de depósito ✔ | EZ2: FECHA | FA2: VIAJES | FB2: MONTO | FC2: Validación de depósito ✔ | FD2: FECHA | FE2: VIAJES | FF2: MONTO | FG2: Validación de depósito ✔ | FH2: FECHA | FI2: VIAJES | FJ2: MONTO | FK2: Validación de depósito ✔ | FL2: FECHA | FM2: VIAJES | FN2: MONTO | FO2: Validación de depósito ✔ | FP2: FECHA | FQ2: VIAJES | FR2: MONTO | FS2: Validación de depósito ✔ | FT2: FECHA | FU2: VIAJES | FV2: MONTO | FW2: Validación de depósito ✔ | FX2: FECHA | FY2: VIAJES | FZ2: MONTO | GA2: Validación de depósito ✔ | GB2: FECHA | GC2: VIAJES | GD2: MONTO | GE2: Validación de depósito ✔ | GF2: FECHA | GG2: VIAJES | GH2: MONTO | GI2: Validación de depósito ✔ | GJ2: FECHA | GK2: VIAJES | GL2: MONTO | GM2: Validación de depósito ✔ | GN2: FECHA | GO2: VIAJES | GP2: MONTO | GQ2: Validación de depósito ✔ | GR2: FECHA | GS2: VIAJES | GT2: MONTO | GU2: Validación de depósito ✔ | GV2: FECHA | GW2: VIAJES | GX2: MONTO | GY2: Validación de depósito ✔ | GZ2: FECHA | HA2: VIAJES | HB2: MONTO | HC2: Validación de depósito ✔ | HD2: FECHA | HE2: VIAJES | HF2: MONTO | HG2: Validación de depósito ✔ | HH2: FECHA | HI2: VIAJES | HJ2: MONTO | HK2: Validación de depósito ✔ | HL2: FECHA | HM2: VIAJES | HN2: MONTO | HO2: Validación de depósito ✔
A3: 1 | B3: ACTIVO | C3: CHEVROLET ONIX JOY | D3: AUTOS SEGUNDO USO - 2025 | E3: Z7C202 | F3: 130 | G3: 45447986 | H3: 935 706 230 | I3: Machacuay Ramos Alexander Paul | J3: 600 | K3: COMPLETA | L3: =IFERROR(__xludf.DUMMYFUNCTION("MAX( ARRAYFORMULA( IF( P3:ACD3<>"""", IFERROR(VALUE(REGEXEXTRACT(P$1:ACD$1,""\d+"")),0), 0 ) ) ) "),52) -> 52 | M3: =IFERROR(__xludf.DUMMYFUNCTION("COUNTIF( FILTER(T3:ACC3, REGEXMATCH(T$2:ACC$2,""Validación"")), ""❌"" ) "),0) -> 0 | N3: =SUM(R3+V3+Z3+AD3+AH3+AL3+AP3+AT3+AX3+BB3+BF3+BJ3+BN3+BR3+BV3+BZ3+CD3+CH3+CL3+CP3+CT3+CX3+DB3+DF3+DJ3+DN3+DR3+DV3+DZ3+ED3+EH3+EL3+EP3+ET3+FB3+FF3+FJ3+FN3+FR3+FV3+FZ3+GD3) -> 5461.21 | O3: =N3+J3 -> 6061.21 | P3: 45817 | Q3: - | R3: 137 | S3: ✔ | T3: 45810 | U3: 127 | V3: 107 | W3: ✔ | X3: 45818 | Y3: 127 | Z3: 107 | AA3: ✔ | AB3: 45825 | AC3: 45 | AD3: 127 | AE3: ✔ | AF3: 45831 | AG3: 120 | AH3: 107 | AI3: ✔ | AJ3: 45838 | AK3: 140 | AL3: 102 | AM3: ✔ | AN3: 45846 | AO3: 165 | AP3: 97 | AQ3: ✔ | AR3: 45853 | AS3: 165 | AT3: 97 | AU3: ✔ | AV3: 45859 | AW3: 160 | AX3: 97 | AY3: ✔ | AZ3: 45867 | BA3: 167 | BB3: 98.38 | BC3: ✔ | BD3: 45874 | BE3: 165 | BF3: 97 | BG3: ✔ | BH3: 45880 | BI3: 165 | BJ3: 99.8 | BK3: ✔ | BL3: 45887 | BM3: 166 | BN3: 98.4 | BO3: ✔ | BP3: 45894 | BQ3: 170 | BR3: 97 | BS3: ✔ | BT3: 45901 | BU3: 175 | BV3: 376.5 | BW3: ✔ | BX3: 45908 | BY3: 175 | BZ3: 341.5 | CA3: ✔ | CB3: 45915 | CC3: 141 | CD3: 116.6 | CE3: ✔ | CF3: 45922 | CG3: 177 | CH3: 110.87 | CI3: ✔ | CJ3: 45929 | CK3: 176 | CL3: 112.56 | CM3: ✔ | CN3: 45936 | CO3: 175 | CP3: 106.7 | CQ3: ✔ | CR3: 45943 | CS3: 142 | CT3: 122.4 | CU3: ✔ | CV3: 45950 | CW3: 142 | CX3: 133 | CY3: ✔ | CZ3: 45957 | DA3: 175 | DB3: 97 | DC3: ✔ | DD3: 45964 | DE3: 155 | DF3: 119 | DG3: ✔ | DH3: 45971 | DI3: 155 | DJ3: 132.6 | DK3: ✔ | DL3: 45978 | DM3: 122 | DN3: 128.4 | DO3: ✔ | DP3: 45985 | DQ3: 164 | DR3: 137.18 | DS3: ✔ | DT3: 45992 | DU3: 145 | DV3: 134 | DW3: ✔ | DX3: 45999 | DY3: 152 | DZ3: 161 | EA3: ✔ | EB3: 46006 | EC3: 179 | ED3: 147 | EE3: ✔ | EF3: 46013 | EG3: 181 | EH3: 145.5 | EI3: ✔ | EJ3: 46020 | EK3: 180 | EL3: 150.18 | EM3: ✔ | EN3: 46027 | EO3: 42 | EP3: 243.44 | EQ3: ✔ | ER3: 46034 | ES3: 181 | ET3: 97 | EU3: ✔ | EV3: 46041 | EW3: 180 | EX3: 201.77 | EY3: ✔ | EZ3: 46048 | FA3: 133 | FB3: 97 | FC3: ✔ | FD3: 46055 | FE3: 187 | FF3: 131.6 | FG3: ✔ | FH3: 46062 | FI3: 187 | FJ3: 97 | FK3: ✔ | FL3: 46069 | FM3: 92 | FN3: 109.1 | FO3: ✔ | FP3: 46076 | FQ3: 146 | FR3: 103.5 | FS3: ✔ | FT3: 46083 | FU3: 144 | FV3: 102 | FW3: ✔ | FX3: 46090 | FY3: 90 | FZ3: 123 | GA3: ✔ | GB3: 46097 | GC3: 92 | GD3: 117 | GE3: ✔ | GF3: 46104 | GG3: 60 | GH3: 158.54 | GI3: ✔ | GJ3: 46111 | GK3: 191 | GL3: 116.46 | GM3: ✔ | GN3: 46118 | GO3: 191 | GP3: 161.44 | GQ3: ✔ | GR3: 46125 | GS3: 191 | GT3: 148.75 | GU3: ✔ | GV3: 46132 | GW3: 191 | GX3: 97 | GY3: ✔ | GZ3: 46139 | HA3: 191 | HB3: 97 | HC3: ✔ | HD3: 46146 | HE3: 40 | HF3: 141.44 | HG3: ✔ | HH3: 46153 | HI3: 100 | HJ3: 115.19 | HK3: ✔ | HL3: 46160 | HM3: 190 | HN3: 97 | HO3: ✔
A4: 2 | B4: ACTIVO | C4: TOYOTA YARIS | D4: AUTOS SEGUNDO USO - 2025 | E4: AEJ391 | F4: 130 | G4: 41689665 | H4: 926 934 333 | I4: López Shiroma Luis Alberto | J4: 600 | K4: COMPLETA | L4: =IFERROR(__xludf.DUMMYFUNCTION("MAX( ARRAYFORMULA( IF( P4:ACD4<>"""", IFERROR(VALUE(REGEXEXTRACT(P$1:ACD$1,""\d+"")),0), 0 ) ) ) "),48) -> 48 | M4: =IFERROR(__xludf.DUMMYFUNCTION("COUNTIF( FILTER(T4:ACC4, REGEXMATCH(T$2:ACC$2,""Validación"")), ""❌"" ) "),3) -> 3 | N4: =SUM(R4+V4+Z4+AD4+AH4+AL4+AP4+AT4+AX4+BB4+BF4+BJ4+BN4+BR4+BV4+BZ4+CD4+CH4+CL4+CP4+CT4+CX4+DB4+DF4+DJ4+DN4+DR4+DV4+DZ4+ED4+EH4+EL4+EP4+ET4+EX4+FB4+FF4+FJ4+FN4+FR4) -> 4736.07 | O4: =N4+J4 -> 5336.07 | P4: 45818 | Q4: DEPÓSITO | R4: 142 | S4: ✔ | T4: 45839 | U4: 138 | V4: 112 | W4: ✔ | X4: 45845 | Y4: 140 | Z4: 107 | AA4: ✔ | AB4: 45852 | AC4: 111 | AD4: 117 | AE4: ✔ | AF4: 45859 | AG4: 112 | AH4: 118.67 | AI4: ✔ | AJ4: 45866 | AK4: 116 | AL4: 117 | AM4: ✔ | AN4: 45872 | AO4: 162 (YP +YB) | AP4: 102 | AQ4: ✔ | AR4: 45880 | AS4: 140 | AT4: 107 | AU4: ✔ | AV4: 45887 | AW4: 140 | AX4: 107 | AY4: ✔ | AZ4: 45894 | BA4: 127 | BB4: 112 | BC4: ✔ | BD4: 45901 | BE4: 145 | BF4: 107 | BG4: ✔ | BH4: 45908 | BI4: 150 | BJ4: 107 | BK4: ✔ | BL4: 45915 | BM4: 141 | BN4: 107 | BO4: ✔ | BP4: 45922 | BQ4: 120 | BR4: 112 | BS4: ✔ | BT4: 45929 | BU4: 121 | BV4: 112 | BW4: ✔ | BX4: 45936 | BY4: 155 | BZ4: 107 | CA4: ✔ | CB4: 45943 | CC4: 111 | CD4: 117 | CE4: ✔ | CF4: 45950 | CG4: 126 | CH4: 112 | CI4: ✔ | CJ4: 45957 | CK4: 151 | CL4: 107 | CM4: ✔ | CN4: 45964 | CO4: 125 | CP4: 112 | CQ4: ✔ | CR4: 45971 | CS4: 123 | CT4: 112 | CU4: ✔ | CV4: 45978 | CW4: 79 | CX4: 127 | CY4: ✔ | CZ4: 45985 | DA4: 80 | DB4: 122 | DC4: ✔ | DD4: 45992 | DE4: 83 | DF4: 122 | DG4: ✔ | DH4: 45999 | DI4: 80 | DJ4: 122 | DK4: ✔ | DL4: 46006 | DM4: 80 | DN4: 122 | DO4: ✔ | DP4: 46013 | DQ4: 80 | DR4: 122 | DS4: ✔ | DT4: 46020 | DU4: 80 | DV4: 122 | DW4: ✔ | DX4: 46027 | DY4: 82 | DZ4: 122 | EA4: ✔ | EB4: 46034 | EC4: 86 | ED4: 122 | EE4: ✔ | EF4: 46041 | EG4: 86 | EH4: 122 | EI4: ✔ | EJ4: 46048 | EK4: 122 | EL4: 112 | EM4: ✔ | EN4: 46055 | EO4: 86 | EP4: 122 | EQ4: ✔ | ER4: 46062 | ES4: 96 | ET4: 122 | EU4: ✔ | EV4: 46069 | EW4: 92 | EX4: 122 | EY4: ✔ | EZ4: 46076 | FA4: 82 | FB4: 122 | FC4: ✔ | FD4: 46083 | FE4: 110 | FF4: 122 | FG4: ✔ | FH4: 46090 | FI4: 30 | FJ4: 150.5 | FK4: ✔ | FL4: 46097 | FM4: 55 | FN4: 145.2 | FO4: ✔ | FP4: 46104 | FQ4: 78 | FR4: 139.7 | FS4: ✔ | FT4: 46111 | FU4: 78 | FV4: 152.4 | FW4: ✔ | FX4: 46118 | FY4: 75 | FZ4: 167.64 | GA4: ✔ | GB4: 46125 | GC4: 35 | GD4: 171.82 | GE4: ✔ | GF4: 46132 | GG4: 10 | GH4: 170.4 | GI4: ✔ | GJ4: 46139 | GK4: 12 | GL4: 168.19 | GM4: ❌ | GN4: 46146 | GO4: 43 | GP4: 142 | GQ4: ✔ | GR4: 46153 | GS4: 38 | GT4: 142 | GU4: ❌ | GV4: 46160 | GW4: 50 | GX4: 142 | GY4: ❌
A5: 3 | B5: ACTIVO | C5: HYUNDAI ACCENT | D5: AUTOS SEMINUEVOS 2025 - I | E5: CLE349 | F5: 230 | G5: 10632789 | H5: 997474254 - 991310154 | I5: Posadas montesinos William | J5: 1000 | K5: COMPLETA | L5: =IFERROR(__xludf.DUMMYFUNCTION("MAX( ARRAYFORMULA( IF( P5:ACD5<>"""", IFERROR(VALUE(REGEXEXTRACT(P$1:ACD$1,""\d+"")),0), 0 ) ) ) "),44) -> 44 | M5: =IFERROR(__xludf.DUMMYFUNCTION("COUNTIF( FILTER(T5:ACC5, REGEXMATCH(T$2:ACC$2,""Validación"")), ""❌"" ) "),0) -> 0 | N5: =SUM(R5+V5+Z5+AD5+AH5+AL5+AP5+AT5+AX5+BB5+BF5+BJ5+BN5+BR5+BV5+BZ5+CD5+CH5+CL5+CP5+CT5+CX5+DB5+DF5+DJ5+DN5+DR5+DV5+DZ5+ED5+EH5+EL5+EP5+ET5+EX5+FB5+FF5) -> 4610.02 | O5: =N5+J5 -> 5610.02 | P5: 45852 | Q5: DEPÓSITO | R5: 150 | S5: ✔ | T5: 45866 | U5: 165 | V5: 110 | W5: ✔ | X5: 45873 | Y5: 137 | Z5: 120 | AA5: ✔ | AB5: 45880 | AC5: 168 | AD5: 110 | AE5: ✔ | AF5: 45887 | AG5: 170 | AH5: 111.6 | AI5: ✔ | AJ5: 45894 | AK5: 142 | AL5: 116.6 | AM5: ✔ | AN5: 45901 | AO5: 177 | AP5: 110 | AQ5: ✔ | AR5: 45908 | AS5: 175 | AT5: 110 | AU5: ✔ | AV5: 45915 | AW5: 176 | AX5: 110 | AY5: ✔ | AZ5: 45922 | BA5: 150 | BB5: 115 | BC5: ✔ | BD5: 45929 | BE5: 150 | BF5: 115 | BG5: ✔ | BH5: 45936 | BI5: 153 | BJ5: 115 | BK5: ✔ | BL5: 45943 | BM5: 158 | BN5: 115 | BO5: ✔ | BP5: 45950 | BQ5: 153 | BR5: 116.64 | BS5: ✔ | BT5: 45957 | BU5: 151 | BV5: 115 | BW5: ✔ | BX5: 45964 | BY5: 151 | BZ5: 116.64 | CA5: ✔ | CB5: 45971 | CC5: 153 | CD5: 118.28 | CE5: ✔ | CF5: 45978 | CG5: 128 | CH5: 121.64 | CI5: ✔ | CJ5: 45985 | CK5: 130 | CL5: 123.42 | CM5: ✔ | CN5: 45992 | CO5: 132 | CP5: 123.42 | CQ5: ✔ | CR5: 45999 | CS5: 146 | CT5: 118.42 | CU5: ✔ | CV5: 46006 | CW5: 139 | CX5: 126.84 | CY5: ✔ | CZ5: 46013 | DA5: 137 | DB5: 132 | DC5: ✔ | DD5: 46020 | DE5: 137 | DF5: 144 | DG5: ✔ | DH5: 46027 | DI5: 106 | DJ5: 150 | DK5: ✔ | DL5: 46034 | DM5: 140 | DN5: 138 | DO5: ✔ | DP5: 46041 | DQ5: 156 | DR5: 136.34 | DS5: ✔ | DT5: 46048 | DU5: 149 | DV5: 129.78 | DW5: ✔ | DX5: 46055 | DY5: 132 | DZ5: 133 | EA5: ✔ | EB5: 46062 | EC5: 129 | ED5: 132.9 | EE5: ✔ | EF5: 46069 | EG5: 127 | EH5: 132 | EI5: ✔ | EJ5: 46076 | EK5: 126 | EL5: 133.5 | EM5: ✔ | EN5: 46083 | EO5: 125 | EP5: 132 | EQ5: ✔ | ER5: 46090 | ES5: 131 | ET5: 132 | EU5: ✔ | EV5: 46097 | EW5: 133 | EX5: 132 | EY5: ✔ | EZ5: 46104 | FA5: 140 | FB5: 132 | FC5: ✔ | FD5: 46111 | FE5: 131 | FF5: 132 | FG5: ✔ | FH5: 46118 | FI5: 106 | FJ5: 137.58 | FK5: ✔ | FL5: 46125 | FM5: 103 | FN5: 136.59 | FO5: ✔ | FP5: 46132 | FQ5: 103 | FR5: 133.17 | FS5: ✔ | FT5: 46139 | FU5: 103 | FV5: 154.4 | FW5: ✔ | FX5: 46146 | FY5: 103 | FZ5: 151.49 | GA5: ✔ | GB5: 46153 | GC5: 125 | GD5: 120 | GE5: ✔ | GF5: 46160 | GG5: 102 | GH5: 125 | GI5: ✔
A6: 4 | B6: ACTIVO | C6: HYUNDAI ACCENT | D6: AUTOS SEMINUEVOS 2025 - I | E6: CLH428 | F6: 230 | G6: 41729445 | H6: 904 672 593 | I6: Pacheco David | J6: 1000 | K6: COMPLETA | L6: =IFERROR(__xludf.DUMMYFUNCTION("MAX( ARRAYFORMULA( IF( P6:ACD6<>"""", IFERROR(VALUE(REGEXEXTRACT(P$1:ACD$1,""\d+"")),0), 0 ) ) ) "),42) -> 42 | M6: =IFERROR(__xludf.DUMMYFUNCTION("COUNTIF( FILTER(T6:ACC6, REGEXMATCH(T$2:ACC$2,""Validación"")), ""❌"" ) "),0) -> 0 | N6: =SUM(R6+V6+Z6+AD6+AH6+AL6+AP6+AT6+AX6+BB6+BF6+BJ6+BN6+BR6+BV6+BZ6+CD6+CH6+CL6+CP6+CT6+CX6+DB6+DF6+DJ6+DN6+DR6+DV6+DZ6+ED6+EH6+EL6+EP6+ET6+EX6) -> 4118.91 | O6: =N6+J6 -> 5118.91 | P6: 45873 | Q6: GARANTÍA | R6: 150 | S6: ✔ | T6: 45880 | U6: 140 | V6: 115 | W6: ✔ | X6: 45887 | Y6: 140 | Z6: 115 | AA6: ✔ | AB6: 45894 | AC6: 151 | AD6: 115 | AE6: ✔ | AF6: 45901 | AG6: 146 | AH6: 115 | AI6: ✔ | AJ6: 45908 | AK6: 176 | AL6: 110 | AM6: ✔ | AN6: 45915 | AO6: 84 | AP6: 130 | AQ6: ✔ | AR6: 45922 | AS6: 142 | AT6: 115 | AU6: ✔ | AV6: 45929 | AW6: 142 | AX6: 115 | AY6: ✔ | AZ6: 45936 | BA6: 140 | BB6: 115 | BC6: ✔ | BD6: 45943 | BE6: 168 | BF6: 110 | BG6: ✔ | BH6: 45950 | BI6: 151 | BJ6: 115 | BK6: ✔ | BL6: 45957 | BM6: 152 | BN6: 115 | BO6: ✔ | BP6: 45964 | BQ6: 147 | BR6: 115 | BS6: ✔ | BT6: 45971 | BU6: 145 | BV6: 115 | BW6: ✔ | BX6: 45978 | BY6: 146 | BZ6: 115 | CA6: ✔ | CB6: 45985 | CC6: 180 | CD6: 110 | CE6: ✔ | CF6: 45992 | CG6: 137 | CH6: 120 | CI6: ✔ | CJ6: 45999 | CK6: 160 | CL6: 110 | CM6: ✔ | CN6: 46006 | CO6: 152 | CP6: 115 | CQ6: ✔ | CR6: 46013 | CS6: 147 | CT6: 115 | CU6: ✔ | CV6: 46020 | CW6: 146 | CX6: 115 | CY6: ✔ | CZ6: 46027 | DA6: 60 | DB6: 135 | DC6: ✔ | DD6: 46034 | DE6: 121 | DF6: 120 | DG6: ✔ | DH6: 46041 | DI6: 0 | DJ6: 150 | DK6: ✔ | DL6: 46048 | DM6: 167 | DN6: 110 | DO6: ✔ | DP6: 46055 | DQ6: 146 | DR6: 120 | DS6: ✔ | DT6: 46062 | DU6: 145 | DV6: 121.2 | DW6: ✔ | DX6: 46069 | DY6: 145 | DZ6: 115 | EA6: ✔ | EB6: 46076 | EC6: 153 | ED6: 115 | EE6: ✔ | EF6: 46083 | EG6: 167 | EH6: 109.6 | EI6: ✔ | EJ6: 46090 | EK6: 150 | EL6: 118.11 | EM6: ✔ | EN6: 46097 | EO6: 134 | EP6: 120 | EQ6: ✔ | ER6: 46104 | ES6: 162 | ET6: 110 | EU6: ✔ | EV6: 46111 | EW6: 175 | EX6: 110 | EY6: ✔ | EZ6: 46118 | FA6: 120 | FB6: 120 | FC6: ✔ | FD6: 46125 | FE6: 155 | FF6: 115 | FG6: ✔ | FH6: 46132 | FI6: 155 | FJ6: 115 | FK6: ✔ | FL6: 46139 | FM6: 152 | FN6: 115 | FO6: ✔ | FP6: 46146 | FQ6: 161 | FR6: 110 | FS6: ✔ | FT6: 46153 | FU6: 156 | FV6: 115 | FW6: ✔ | FX6: 46160 | FY6: 152 | FZ6: 115 | GA6: ✔
A7: 5 | B7: ACTIVO | C7: KIA SOLUTO | D7: AUTOS SEMINUEVOS 2025 - I | E7: CRL269 | F7: 230 | G7: 8889181 | H7: 932 492 300 | I7: Rivera José | J7: 1000 | K7: COMPLETA | L7: =IFERROR(__xludf.DUMMYFUNCTION("MAX( ARRAYFORMULA( IF( P7:ACD7<>"""", IFERROR(VALUE(REGEXEXTRACT(P$1:ACD$1,""\d+"")),0), 0 ) ) ) "),42) -> 42 | M7: =IFERROR(__xludf.DUMMYFUNCTION("COUNTIF( FILTER(T7:ACC7, REGEXMATCH(T$2:ACC$2,""Validación"")), ""❌"" ) "),0) -> 0 | N7: =SUM(R7+V7+Z7+AD7+AH7+AL7+AP7+AT7+AX7+BB7+BF7+BJ7+BN7+BR7+BV7+BZ7+CD7+CH7+CL7+CP7+CT7+CX7+DB7+DF7+DJ7+DN7+DR7+DV7+DZ7+ED7) -> 3631.31 | O7: =N7+J7 -> 4631.31 | P7: 45873 | Q7: DEPÓSITO | R7: 142 | S7: ✔ | T7: 45880 | U7: 127 | V7: 112 | W7: ✔ | X7: 45887 | Y7: 165 | Z7: 102 | AA7: ✔ | AB7: 45895 | AC7: 143 | AD7: 108.53 | AE7: ✔ | AF7: 45901 | AG7: 141 | AH7: 108.53 | AI7: ✔ | AJ7: 45908 | AK7: 141 | AL7: 108.53 | AM7: ✔ | AN7: 45915 | AO7: 141 | AP7: 110.06 | AQ7: ✔ | AR7: 45922 | AS7: 143 | AT7: 110.06 | AU7: ✔ | AV7: 45929 | AW7: 140 | AX7: 107 | AY7: ✔ | AZ7: 45936 | BA7: 140 | BB7: 108.53 | BC7: ✔ | BD7: 45943 | BE7: 142 | BF7: 117.7 | BG7: ✔ | BH7: 45950 | BI7: 110 | BJ7: 130.37 | BK7: ✔ | BL7: 45957 | BM7: 140 | BN7: 128.35 | BO7: ✔ | BP7: 45964 | BQ7: 145 | BR7: 140.63 | BS7: ✔ | BT7: 45971 | BU7: 145 | BV7: 111.59 | BW7: ✔ | BX7: 45978 | BY7: 145 | BZ7: 131.46 | CA7: ✔ | CB7: 45985 | CC7: 145 | CD7: 131.46 | CE7: ✔ | CF7: 45992 | CG7: 145 | CH7: 131.46 | CI7: ✔ | CJ7: 45999 | CK7: 145 | CL7: 131.46 | CM7: ✔ | CN7: 46006 | CO7: 120 | CP7: 137.6 | CQ7: ✔ | CR7: 46013 | CS7: 121 | CT7: 145.6 | CU7: ✔ | CV7: 46020 | CW7: 123 | CX7: 147.2 | CY7: ✔ | CZ7: 46027 | DA7: 120 | DB7: 140.8 | DC7: ✔ | DD7: 46034 | DE7: 120 | DF7: 129.62 | DG7: ✔ | DH7: 46041 | DI7: 120 | DJ7: 123.2 | DK7: ✔ | DL7: 46048 | DM7: 120 | DN7: 127 | DO7: ✔ | DP7: 46055 | DQ7: 120 | DR7: 127.1 | DS7: ✔ | DT7: 46062 | DU7: 125 | DV7: 130.42 | DW7: ✔ | DX7: 46069 | DY7: 125 | DZ7: 3.2 | EA7: ✔ | EB7: 46076 | EC7: 108 | ED7: 147.85 | EE7: ✔ | EF7: 46083 | EG7: 125 | EH7: 149.88 | EI7: ✔ | EJ7: 46090 | EK7: 120 | EL7: 130.63 | EM7: ✔ | EN7: 46097 | EO7: 121 | EP7: 136.16 | EQ7: ✔ | ER7: 46104 | ES7: 120 | ET7: 124.8 | EU7: ✔ | EV7: 46111 | EW7: 120 | EX7: 112 | EY7: ✔ | EZ7: 46118 | FA7: 120 | FB7: 112 | FC7: ✔ | FD7: 46125 | FE7: 103 | FF7: 117 | FG7: ✔ | FH7: 46132 | FI7: 109 | FJ7: 117 | FK7: ✔ | FL7: 46139 | FM7: 109 | FN7: 117 | FO7: ✔ | FP7: 46146 | FQ7: 109 | FR7: 117 | FS7: ✔ | FT7: 46153 | FU7: 101 | FV7: 118.61 | FW7: ✔ | FX7: 46160 | FY7: 107 | FZ7: 142 | GA7: ✔
A8: 6 | B8: ACTIVO | C8: KIA SOLUTO | D8: AUTOS SEMINUEVOS 2025 - I | E8: CRL276 | F8: 230 | G8: 43838985 | H8: 926 487 201 | I8: Asencio Cuba Nestor | J8: 1000 | K8: COMPLETA | L8: =IFERROR(__xludf.DUMMYFUNCTION("MAX( ARRAYFORMULA( IF( P8:ACD8<>"""", IFERROR(VALUE(REGEXEXTRACT(P$1:ACD$1,""\d+"")),0), 0 ) ) ) "),41) -> 41 | M8: =IFERROR(__xludf.DUMMYFUNCTION("COUNTIF( FILTER(T8:ACC8, REGEXMATCH(T$2:ACC$2,""Validación"")), ""❌"" ) "),2) -> 2 | N8: =SUM(R8+V8+Z8+AD8+AH8+AL8+AP8+AT8+AX8+BB8+BF8+BJ8+BN8+BR8+BV8+BZ8+CD8+CH8+CL8+CP8+CT8+CX8+DB8+DF8+DJ8+DN8+DR8+DV8+DZ8+ED8+EH8+EL8) -> 3825.26 | O8: =N8+J8 -> 4825.26 | P8: 45880 | Q8: DEPÓSITO | R8: 142 | S8: ✔ | T8: 45887 | U8: 140 | V8: 109 | W8: ✔ | X8: 45894 | Y8: 147 | Z8: 107 | AA8: ✔ | AB8: 45901 | AC8: 191 | AD8: 102 | AE8: ✔ | AF8: 45908 | AG8: 81 | AH8: 125.48 | AI8: ✔ | AJ8: 45915 | AK8: 111 | AL8: 117 | AM8: ✔ | AN8: 45922 | AO8: 145 | AP8: 107 | AQ8: ✔ | AR8: 45929 | AS8: 145 | AT8: 107 | AU8: ✔ | AV8: 45936 | AW8: 142 | AX8: 112 | AY8: ✔ | AZ8: 45943 | BA8: 177 | BB8: 104 | BC8: ✔ | BD8: 45950 | BE8: 101 | BF8: 122 | BG8: ✔ | BH8: 45957 | BI8: 177 | BJ8: 107 | BK8: ✔ | BL8: 45964 | BM8: 129 | BN8: 120 | BO8: ✔ | BP8: 45971 | BQ8: 149 | BR8: 114.64 | BS8: ✔ | BT8: 45978 | BU8: 147 | BV8: 120 | BW8: ✔ | BX8: 45985 | BY8: 49 | BZ8: 145.2 | CA8: ✔ | CB8: 45992 | CC8: 189 | CD8: 106.38 | CE8: ✔ | CF8: 45999 | CG8: 123 | CH8: 132 | CI8: ✔ | CJ8: 46006 | CK8: 147 | CL8: 125.36 | CM8: ✔ | CN8: 46013 | CO8: 146 | CP8: 117.7 | CQ8: ✔ | CR8: 46020 | CS8: 120 | CT8: 129 | CU8: ✔ | CV8: 46027 | CW8: 158 | CX8: 113 | CY8: ✔ | CZ8: 46034 | DA8: 58 | DB8: 145.2 | DC8: ✔ | DD8: 46041 | DE8: 101 | DF8: =110+34.2 -> 144.2 | DG8: ✔ | DH8: 46048 | DI8: 116 | DJ8: 139.5 | DK8: ✔ | DL8: 46055 | DM8: 100 | DN8: 140.4 | DO8: ✔ | DP8: 46062 | DQ8: 149 | DR8: 117.7 | DS8: ✔ | DT8: 46069 | DU8: 151 | DV8: 107 | DW8: ✔ | DX8: 46076 | DY8: 125 | DZ8: 119.5 | EA8: ✔ | EB8: 46083 | EC8: 129 | ED8: 112 | EE8: ✔ | EF8: 46090 | EG8: 152 | EH8: 108 | EI8: ✔ | EJ8: 46097 | EK8: 152 | EL8: 107 | EM8: ✔ | EN8: 46104 | EO8: 154 | EP8: 114.16 | EQ8: ✔ | ER8: 46111 | ES8: 150 | ET8: 139.1 | EU8: ✔ | EV8: 46118 | EW8: 83 | EX8: 185.97 | EY8: ✔ | EZ8: 46125 | FA8: 0 | FB8: 170.15 | FC8: ✔ | FD8: 46132 | FE8: 0 | FF8: 148.32 | FG8: ✔ | FH8: 46139 | FI8: 0 | FJ8: 170.4 | FK8: ✔ | FL8: 46146 | FM8: 0 | FN8: 112.55 | FO8: ✔ | FP8: 46153 | FQ8: 0 | FR8: 142 | FS8: ❌ | FT8: 46160 | FU8: 156 | FV8: 142 | FW8: ❌
A9: 7 | B9: ACTIVO | C9: KIA SOLUTO | D9: AUTOS SEMINUEVOS 2025 - I | E9: CRM163 | F9: 230 | G9: 18201506 | H9: 934 139 376 | I9: Menor Guevara Jose Antonio | J9: 1000 | K9: COMPLETA | L9: =IFERROR(__xludf.DUMMYFUNCTION("MAX( ARRAYFORMULA( IF( P9:ACD9<>"""", IFERROR(VALUE(REGEXEXTRACT(P$1:ACD$1,""\d+"")),0), 0 ) ) ) "),41) -> 41 | M9: =IFERROR(__xludf.DUMMYFUNCTION("COUNTIF( FILTER(T9:ACC9, REGEXMATCH(T$2:ACC$2,""Validación"")), ""❌"" ) "),1) -> 1 | N9: =SUM(R9+V9+Z9+AD9+AH9+AL9+AP9+AT9+AX9+BB9+BF9+BJ9+BN9+BR9+BV9+BZ9+CD9+CH9+CL9+CP9+CT9+CX9+DB9+DF9+DJ9+DN9+DR9+DV9+DZ9+ED9+EH9+EL9+EP9) -> 3615.33 | O9: =N9+J9 -> 4615.33 | P9: 45880 | Q9: DEPÓSITO | R9: 142 | S9: ✔ | T9: 45887 | U9: 170 | V9: 102 | W9: ✔ | X9: 45894 | Y9: 180 | Z9: 102 | AA9: ✔ | AB9: 45901 | AC9: 142 | AD9: 107 | AE9: ✔ | AF9: 45908 | AG9: 179 | AH9: 102 | AI9: ✔ | AJ9: 45915 | AK9: 191 | AL9: 102 | AM9: ✔ | AN9: 45922 | AO9: 191 | AP9: 102 | AQ9: ✔ | AR9: 45929 | AS9: 191 | AT9: 102 | AU9: ✔ | AV9: 45936 | AW9: 191 | AX9: 102 | AY9: ✔ | AZ9: 45943 | BA9: 188 | BB9: 102 | BC9: ✔ | BD9: 45950 | BE9: 187 | BF9: 102 | BG9: ✔ | BH9: 45957 | BI9: 135 | BJ9: 112 | BK9: ✔ | BL9: 45964 | BM9: 135 | BN9: 102 | BO9: ✔ | BP9: 45971 | BQ9: 133 | BR9: 102 | BS9: ✔ | BT9: 45978 | BU9: 120 | BV9: 112 | BW9: ✔ | BX9: 45985 | BY9: 140 | BZ9: 107 | CA9: ✔ | CB9: 45992 | CC9: 142 | CD9: 107 | CE9: ✔ | CF9: 45999 | CG9: 169 | CH9: 102 | CI9: ✔ | CJ9: 46006 | CK9: 169 | CL9: 102 | CM9: ✔ | CN9: 46013 | CO9: 163 | CP9: 102 | CQ9: ✔ | CR9: 46020 | CS9: 159 | CT9: 107 | CU9: ✔ | CV9: 46027 | CW9: 163 | CX9: 102 | CY9: ✔ | CZ9: 46034 | DA9: 134 | DB9: 112 | DC9: ✔ | DD9: 46041 | DE9: 110 | DF9: 117 | DG9: ✔ | DH9: 46048 | DI9: 104 | DJ9: 117 | DK9: ✔ | DL9: 46055 | DM9: 106 | DN9: 117 | DO9: ✔ | DP9: 46062 | DQ9: 111 | DR9: 117 | DS9: ✔ | DT9: 46069 | DU9: 103 | DV9: 117 | DW9: ✔ | DX9: 46076 | DY9: 109 | DZ9: 118.5 | EA9: ✔ | EB9: 46083 | EC9: 89 | ED9: 123.01 | EE9: ✔ | EF9: 46090 | EG9: 72 | EH9: 127.6 | EI9: ✔ | EJ9: 46097 | EK9: 124 | EL9: 112.54 | EM9: ✔ | EN9: 46104 | EO9: 128 | EP9: 112.68 | EQ9: ✔ | ER9: 46111 | ES9: 128 | ET9: 127 | EU9: ✔ | EV9: 46118 | EW9: 30 | EX9: 137.74 | EY9: ✔ | EZ9: 46125 | FA9: 0 | FB9: 142 | FC9: ✔ | FD9: 46132 | FE9: 0 | FF9: 152 | FG9: ✔ | FH9: 46139 | FI9: 0 | FJ9: 152 | FK9: ✔ | FL9: 46146 | FM9: 0 | FN9: 152 | FO9: ✔ | FP9: 46153 | FQ9: 101 | FR9: 117 | FS9: ✔ | FT9: 46160 | FU9: 101 | FV9: 37.73 | FW9: ❌
A10: 8 | B10: ACTIVO | C10: CHEVROLET PRISMA | D10: AUTOS SEGUNDO USO - 2025 | E10: BPU594 | F10: 130 | G10: 7687147 | H10: 916112813 - 987847098 | I10: De las casas Chirinos Eduardo | J10: 600 | K10: COMPLETA | L10: =IFERROR(__xludf.DUMMYFUNCTION("MAX( ARRAYFORMULA( IF( P10:ACD10<>"""", IFERROR(VALUE(REGEXEXTRACT(P$1:ACD$1,""\d+"")),0), 0 ) ) ) "),39) -> 39 | M10: =IFERROR(__xludf.DUMMYFUNCTION("COUNTIF( FILTER(T10:ACC10, REGEXMATCH(T$2:ACC$2,""Validación"")), ""❌"" ) "),2) -> 2 | N10: =SUM(R10+V10+Z10+AD10+AH10+AL10+AP10+AT10+AX10+BB10+BF10+BJ10+BN10+BR10+BV10+BZ10+CD10+CP10+CT10+CX10+DF10+DJ10+DV10+DZ10+ED10+EH10+EL10) -> 3572.74 | O10: =N10+J10 -> 4172.74 | P10: 45894 | Q10: DESCUENTO | R10: 135 | S10: ✔ | T10: 45902 | U10: 141 | V10: 102 | W10: ✔ | X10: 45909 | Y10: 140 | Z10: 103 | AA10: ✔ | AB10: 45915 | AC10: 85 | AD10: 129 | AE10: ✔ | AF10: 45922 | AG10: 138 | AH10: 126 | AI10: ✔ | AJ10: 45929 | AK10: 145 | AL10: 110 | AM10: ✔ | AN10: 45936 | AO10: 123 | AP10: 110 | AQ10: ✔ | AR10: 45943 | AS10: 123 | AT10: 126 | AU10: ✔ | AV10: 45950 | AW10: 142 | AX10: 114.29 | AY10: ✔ | AZ10: 45957 | BA10: 142 | BB10: 132.86 | BC10: ✔ | BD10: 45964 | BE10: 142 | BF10: 122.83 | BG10: ✔ | BH10: 45971 | BI10: 145 | BJ10: 122.82 | BK10: ✔ | BL10: 45978 | BM10: 124 | BN10: 160 | BO10: ✔ | BP10: 45985 | BQ10: 88 | BR10: 164.28 | BS10: ✔ | BT10: 45992 | BU10: 121 | BV10: 157 | BW10: ✔ | BX10: 45999 | BY10: 121 | BZ10: 263.4 | CA10: ✔ | CB10: 46006 | CC10: 28 | CD10: 216.16 | CE10: ✔ | CF10: 46013 | CG10: 16 | CH10: 301.81 | CI10: ✔ | CJ10: 46020 | CK10: 19 | CL10: 379.9 | CM10: ✔ | CN10: 46027 | CO10: 35 | CP10: 157 | CQ10: ✔ | CR10: 46034 | CS10: 57 | CT10: 137 | CU10: ✔ | CV10: 46041 | CW10: 45 | CX10: 125 | CY10: ✔ | CZ10: 46048 | DA10: 149 | DB10: 237.4 | DC10: ✔ | DD10: 46055 | DE10: 158 | DF10: 100 | DG10: ✔ | DH10: 46062 | DI10: 147 | DJ10: 110 | DK10: ✔ | DL10: 46069 | DM10: 145 | DN10: 204.37 | DO10: ✔ | DP10: 46076 | DQ10: 83 | DR10: 222.13 | DS10: ✔ | DT10: 46083 | DU10: 145 | DV10: 113.1 | DW10: ✔ | DX10: 46090 | DY10: 120 | DZ10: 105 | EA10: ✔ | EB10: 46097 | EC10: 120 | ED10: 115.5 | EE10: ✔ | EF10: 46104 | EG10: 150 | EH10: 100 | EI10: ✔ | EJ10: 46111 | EK10: 121 | EL10: 115.5 | EM10: ✔ | EN10: 46118 | EO10: 120 | EP10: 181.42 | EQ10: ✔ | ER10: 46125 | ES10: 0 | ET10: 135 | EU10: ✔ | EV10: 46132 | EW10: 0 | EX10: 148.5 | EY10: ✔ | EZ10: 46139 | FA10: 0 | FB10: 135 | FC10: ✔ | FD10: 46146 | FE10: 0 | FF10: 135 | FG10: ✔ | FH10: 46153 | FI10: 0 | FJ10: 73.3 | FK10: ❌ | FL10: 46160 | FM10: 0 | FN10: 135 | FO10: ❌
A11: 9 | B11: ACTIVO | C11: HYUNDAI ACCENT | D11: AUTOS SEMINUEVOS 2025 - I | E11: CLI166 | F11: 230 | G11: 43321714 | H11: 913330303 - 979847017 | I11: Peña Agurto Eduardo Hector | J11: 1000 | K11: COMPLETA | L11: =IFERROR(__xludf.DUMMYFUNCTION("MAX( ARRAYFORMULA( IF( P11:ACD11<>"""", IFERROR(VALUE(REGEXEXTRACT(P$1:ACD$1,""\d+"")),0), 0 ) ) ) "),39) -> 39 | M11: =IFERROR(__xludf.DUMMYFUNCTION("COUNTIF( FILTER(T11:ACC11, REGEXMATCH(T$2:ACC$2,""Validación"")), ""❌"" ) "),1) -> 1 | N11: =SUM(R11+V11+Z11+AD11+AH11+AL11+AP11+AT11+AX11+BB11+BF11+BJ11+BN11+BR11+BV11+BZ11+CD11+CH11+CL11+CP11+CT11+CX11+DB11+DF11+DJ11+DN11+DR11+DV11+DZ11+ED11) -> 4306.86 | O11: =N11+J11 -> 5306.86 | P11: 45894 | Q11: DEPÓSITO | R11: 150 | S11: ✔ | T11: 45901 | U11: 145 | V11: 115 | W11: ✔ | X11: 45908 | Y11: 145 | Z11: 120 | AA11: ✔ | AB11: 45915 | AC11: 140 | AD11: 138 | AE11: ✔ | AF11: 45922 | AG11: 134 | AH11: 146 | AI11: ✔ | AJ11: 45929 | AK11: 134 | AL11: 160 | AM11: ✔ | AN11: 45936 | AO11: 143 | AP11: 140 | AQ11: ✔ | AR11: 45943 | AS11: 143 | AT11: 140 | AU11: ✔ | AV11: 45950 | AW11: 141 | AX11: 140 | AY11: ✔ | AZ11: 45957 | BA11: 140 | BB11: 140 | BC11: ✔ | BD11: 45964 | BE11: 125 | BF11: 151 | BG11: ✔ | BH11: 45971 | BI11: 123 | BJ11: 145.71 | BK11: ✔ | BL11: 45978 | BM11: 98 | BN11: 156 | BO11: ✔ | BP11: 45985 | BQ11: 122 | BR11: 149 | BS11: ✔ | BT11: 45992 | BU11: 122 | BV11: 147 | BW11: ✔ | BX11: 45999 | BY11: 124 | BZ11: 150.84 | CA11: ✔ | CB11: 46006 | CC11: 122 | CD11: 159 | CE11: ✔ | CF11: 46013 | CG11: 126 | CH11: 156 | CI11: ✔ | CJ11: 46020 | CK11: 96 | CL11: 161.58 | CM11: ✔ | CN11: 46027 | CO11: 121 | CP11: 147.42 | CQ11: ✔ | CR11: 46034 | CS11: 134 | CT11: 140.1 | CU11: ✔ | CV11: 46041 | CW11: 121 | CX11: 136.99 | CY11: ✔ | CZ11: 46048 | DA11: 123 | DB11: 144 | DC11: ✔ | DD11: 46055 | DE11: 122 | DF11: 123.5 | DG11: ✔ | DH11: 46062 | DI11: 126 | DJ11: 133.68 | DK11: ✔ | DL11: 46069 | DM11: 126 | DN11: 134.8 | DO11: ✔ | DP11: 46076 | DQ11: 125 | DR11: 122.17 | DS11: ✔ | DT11: 46083 | DU11: 75 | DV11: 156.21 | DW11: ✔ | DX11: 46090 | DY11: 121 | DZ11: 145.2 | EA11: ✔ | EB11: 46097 | EC11: 95 | ED11: 157.66 | EE11: ✔ | EF11: 46104 | EG11: 122 | EH11: 151.39 | EI11: ✔ | EJ11: 46111 | EK11: 122 | EL11: 144 | EM11: ✔ | EN11: 46118 | EO11: 93 | EP11: 192.2 | EQ11: ✔ | ER11: 46125 | ES11: 93 | ET11: 158.6 | EU11: ✔ | EV11: 46132 | EW11: 125 | EX11: 165.1 | EY11: ✔ | EZ11: 46139 | FA11: 126 | FB11: 165 | FC11: ✔ | FD11: 46146 | FE11: 126 | FF11: 155.15 | FG11: ✔ | FH11: 46153 | FI11: 122 | FJ11: 132 | FK11: ✔ | FL11: 46160 | FM11: 126 | FN11: 98.97 | FO11: ❌
A12: 10 | B12: ACTIVO | C12: HYUNDAI ACCENT | D12: AUTOS SEMINUEVOS 2025 - I | E12: CLH429 | F12: 230 | G12: 9823640 | H12: 931 106 426 | I12: Robles Jose Luis | J12: 1000 | K12: COMPLETA | L12: =IFERROR(__xludf.DUMMYFUNCTION("MAX( ARRAYFORMULA( IF( P12:ACD12<>"""", IFERROR(VALUE(REGEXEXTRACT(P$1:ACD$1,""\d+"")),0), 0 ) ) ) "),39) -> 39 | M12: =IFERROR(__xludf.DUMMYFUNCTION("COUNTIF( FILTER(T12:ACC12, REGEXMATCH(T$2:ACC$2,""Validación"")), ""❌"" ) "),0) -> 0 | N12: =SUM(R12+V12+Z12+AD12+AH12+AL12+AP12+AT12+AX12+BB12+BF12+BJ12+BN12+BR12+BV12+BZ12+CD12+CH12+CL12+CP12+CT12+CX12+DB12+DF12+DJ12+DN12+DR12+DV12+DZ12+ED12+EH12+EL12+EP12+ET12+EX12) -> 4540.97 | O12: =N12+J12 -> 5540.97 | P12: 45894 | Q12: DEPÓSITO | R12: 150 | S12: ✔ | T12: 45901 | U12: 84 | V12: 132 | W12: ✔ | X12: 45908 | Y12: 111 | Z12: 127 | AA12: ✔ | AB12: 45915 | AC12: 86 | AD12: 135 | AE12: ✔ | AF12: 45922 | AG12: 121 | AH12: 127 | AI12: ✔ | AJ12: 45929 | AK12: 120 | AL12: 127 | AM12: ✔ | AN12: 45936 | AO12: 112 | AP12: 127 | AQ12: ✔ | AR12: 45943 | AS12: 95 | AT12: 133 | AU12: ✔ | AV12: 45950 | AW12: 111 | AX12: 125 | AY12: ✔ | AZ12: 45957 | BA12: 92 | BB12: 136 | BC12: ✔ | BD12: 45964 | BE12: 102 | BF12: 131 | BG12: ✔ | BH12: 45971 | BI12: 103 | BJ12: 138 | BK12: ✔ | BL12: 45978 | BM12: 122 | BN12: 132 | BO12: ✔ | BP12: 45985 | BQ12: 81 | BR12: 143 | BS12: ✔ | BT12: 45992 | BU12: 84 | BV12: 150 | BW12: ✔ | BX12: 45999 | BY12: 102 | BZ12: 137.5 | CA12: ✔ | CB12: 46006 | CC12: 103 | CD12: 125 | CE12: ✔ | CF12: 46013 | CG12: 122 | CH12: 120 | CI12: ✔ | CJ12: 46020 | CK12: 121 | CL12: 121.71 | CM12: ✔ | CN12: 46027 | CO12: 102 | CP12: 126.79 | CQ12: ✔ | CR12: 46034 | CS12: 103 | CT12: 127 | CU12: ✔ | CV12: 46041 | CW12: 102 | CX12: 126.79 | CY12: ✔ | CZ12: 46048 | DA12: 124 | DB12: 120 | DC12: ✔ | DD12: 46055 | DE12: 103 | DF12: 125 | DG12: ✔ | DH12: 46062 | DI12: 107 | DJ12: 125.5 | DK12: ✔ | DL12: 46069 | DM12: 127 | DN12: 120 | DO12: ✔ | DP12: 46076 | DQ12: 100 | DR12: 125 | DS12: ✔ | DT12: 46083 | DU12: 104 | DV12: 125.73 | DW12: ✔ | DX12: 46090 | DY12: 101 | DZ12: 125.3 | EA12: ✔ | EB12: 46097 | EC12: 96 | ED12: 130.09 | EE12: ✔ | EF12: 46104 | EG12: 96 | EH12: 131.13 | EI12: ✔ | EJ12: 46111 | EK12: 96 | EL12: 140.43 | EM12: ✔ | EN12: 46118 | EO12: 105 | EP12: 125 | EQ12: ✔ | ER12: 46125 | ES12: 105 | ET12: 125 | EU12: ✔ | EV12: 46132 | EW12: 107 | EX12: 125 | EY12: ✔ | EZ12: 46139 | FA12: 107 | FB12: 125 | FC12: ✔ | FD12: 46146 | FE12: 107 | FF12: 125 | FG12: ✔ | FH12: 46153 | FI12: 107 | FJ12: 126.87 | FK12: ✔ | FL12: 46160 | FM12: 107 | FN12: 125 | FO12: ✔
A13: 11 | B13: ACTIVO | C13: KIA SOLUTO - 0KM | D13: AUTOS 0KM - 2025 | E13: CRM590 | F13: 261 | G13: 8666024 | H13: 980 447 047 | I13: Santillán del Castillo Jorge Luis | J13: 1000 | K13: COMPLETA | L13: =IFERROR(__xludf.DUMMYFUNCTION("MAX( ARRAYFORMULA( IF( P13:ACD13<>"""", IFERROR(VALUE(REGEXEXTRACT(P$1:ACD$1,""\d+"")),0), 0 ) ) ) "),38) -> 38 | M13: =IFERROR(__xludf.DUMMYFUNCTION("COUNTIF( FILTER(T13:ACC13, REGEXMATCH(T$2:ACC$2,""Validación"")), ""❌"" ) "),2) -> 2 | N13: =SUM(R13+V13+Z13+AD13+AH13+AL13+AP13+AT13+AX13+BB13+BF13+BJ13+BN13+BR13+BV13+BZ13+CD13+CH13+CL13+CP13+CT13+CX13+DB13+DF13+DJ13+DN13+DR13+DV13+DZ13+ED13+EH13+EL13+EP13+ET13+EX13) -> 19496.78 | O13: =N13+(J13*3.5) -> 22996.78 | P13: 45902 | Q13: DEPÓSITO | R13: 500 | S13: ✔ | T13: 45908 | U13: 82 | V13: 542.84 | W13: ✔ | X13: 45915 | Y13: 80 | Z13: 621.42 | AA13: ✔ | AB13: 45922 | AC13: 81 | AD13: 614.28 | AE13: ✔ | AF13: 45929 | AG13: 120 | AH13: 598 | AI13: ✔ | AJ13: 45936 | AK13: 121 | AL13: 604.57 | AM13: ✔ | AN13: 45943 | AO13: 120 | AP13: 584.85 | AQ13: ✔ | AR13: 45950 | AS13: 119 | AT13: 598 | AU13: ✔ | AV13: 45957 | AW13: 113 | AX13: 637 | AY13: ✔ | AZ13: 45964 | BA13: 131 | BB13: 598 | BC13: ✔ | BD13: 45971 | BE13: 123 | BF13: 598 | BG13: ✔ | BH13: 45978 | BI13: 121 | BJ13: 598 | BK13: ✔ | BL13: 45985 | BM13: 122 | BN13: 615 | BO13: ✔ | BP13: 45992 | BQ13: 122 | BR13: 598 | BS13: ✔ | BT13: 45999 | BU13: 101 | BV13: 650.24 | BW13: ✔ | BX13: 46006 | BY13: 131 | BZ13: 470 | CA13: ✔ | CB13: 46013 | CC13: 103 | CD13: 481.72 | CE13: ✔ | CF13: 46020 | CG13: 105 | CH13: 637 | CI13: ✔ | CJ13: 46027 | CK13: 105 | CL13: 588 | CM13: ✔ | CN13: 46034 | CO13: 103 | CP13: 588 | CQ13: ✔ | CR13: 46041 | CS13: 102 | CT13: 570 | CU13: ✔ | CV13: 46048 | CW13: 122 | CX13: 541.3 | CY13: ✔ | CZ13: 46055 | DA13: 122 | DB13: 521 | DC13: ✔ | DD13: 46062 | DE13: 107 | DF13: 561.8 | DG13: ✔ | DH13: 46069 | DI13: 107 | DJ13: 541 | DK13: ✔ | DL13: 46076 | DM13: 107 | DN13: 547.8 | DO13: ✔ | DP13: 46083 | DQ13: 102 | DR13: 539 | DS13: ✔ | DT13: 46090 | DU13: 96 | DV13: 490 | DW13: ✔ | DX13: 46097 | DY13: 96 | DZ13: 490 | EA13: ✔ | EB13: 46104 | EC13: 96 | ED13: 490 | EE13: ✔ | EF13: 46111 | EG13: 99 | EH13: 491.45 | EI13: ✔ | EJ13: 46118 | EK13: 100 | EL13: 490 | EM13: ✔ | EN13: 46125 | EO13: 100 | EP13: 490 | EQ13: ✔ | ER13: 46132 | ES13: 102 | ET13: 490 | EU13: ✔ | EV13: 46139 | EW13: 79 | EX13: 520.51 | EY13: ✔ | EZ13: 46146 | FA13: 81 | FB13: 529.92 | FC13: ✔ | FD13: 46153 | FE13: 80 | FF13: 226.14 | FG13: ❌ | FH13: 46160 | FI13: 79 | FJ13: 500 | FK13: ❌
A14: 12 | B14: ACTIVO | C14: KIA SOLUTO - 0KM | D14: AUTOS 0KM - 2025 | E14: CRL050 | F14: 261 | G14: 72795009 | H14: 938 181 064 | I14: Apaza Mita Juan Manuel | J14: 1000 | K14: COMPLETA | L14: =IFERROR(__xludf.DUMMYFUNCTION("MAX( ARRAYFORMULA( IF( P14:ACD14<>"""", IFERROR(VALUE(REGEXEXTRACT(P$1:ACD$1,""\d+"")),0), 0 ) ) ) "),37) -> 37 | M14: =IFERROR(__xludf.DUMMYFUNCTION("COUNTIF( FILTER(T14:ACC14, REGEXMATCH(T$2:ACC$2,""Validación"")), ""❌"" ) "),0) -> 0 | N14: =SUM(R14+V14+Z14+AD14+AH14+AL14+AP14+AT14+AX14+BB14+BF14+BJ14+BN14+BR14+BV14+BZ14+CD14+CH14+CL14+CP14+CT14+CX14+DB14+DF14+DJ14+DN14+DR14+DV14+DZ14+ED14+EH14) -> 15156.39 | O14: =N14+(J14*3.5) -> 18656.39 | P14: 45908 | Q14: DEPÓSITO | R14: 500 | S14: ✔ | T14: 45915 | U14: 112 | V14: 501 | W14: ✔ | X14: 45922 | Y14: 131 | Z14: 496 | AA14: ✔ | AB14: 45929 | AC14: 179 | AD14: 473 | AE14: ✔ | AF14: 45936 | AG14: 177 | AH14: 473 | AI14: ✔ | AJ14: 45943 | AK14: 185 | AL14: 475.75 | AM14: ✔ | AN14: 45950 | AO14: 85 | AP14: 550 | AQ14: ✔ | AR14: 45957 | AS14: 126 | AT14: 506 | AU14: ✔ | AV14: 45964 | AW14: 63 | AX14: 582 | AY14: ✔ | AZ14: 45971 | BA14: 61 | BB14: 600 | BC14: ✔ | BD14: 45978 | BE14: 184 | BF14: 484.4 | BG14: ✔ | BH14: 45985 | BI14: 98 | BJ14: 636.32 | BK14: ✔ | BL14: 45992 | BM14: 182 | BN14: 528 | BO14: ✔ | BP14: 45999 | BQ14: 50 | BR14: 521 | BS14: ✔ | BT14: 46006 | BU14: 126 | BV14: 473.14 | BW14: ✔ | BX14: 46013 | BY14: 126 | BZ14: 547 | CA14: ✔ | CB14: 46020 | CC14: 181 | CD14: 461.8 | CE14: ✔ | CF14: 46027 | CG14: 126 | CH14: 505.98 | CI14: ✔ | CJ14: 46034 | CK14: 182 | CL14: 440 | CM14: ✔ | CN14: 46041 | CO14: 181 | CP14: 432 | CQ14: ✔ | CR14: 46048 | CS14: 181 | CT14: 400 | CU14: ✔ | CV14: 46055 | CW14: 146 | CX14: 460 | CY14: ✔ | CZ14: 46062 | DA14: 187 | DB14: 400 | DC14: ✔ | DD14: 46069 | DE14: 106 | DF14: 490 | DG14: ✔ | DH14: 46076 | DI14: 101 | DJ14: 501.2 | DK14: ✔ | DL14: 46083 | DM14: 101 | DN14: 539.3 | DO14: ✔ | DP14: 46090 | DQ14: 75 | DR14: 425.2 | DS14: ✔ | DT14: 46097 | DU14: 99 | DV14: 544.3 | DW14: ✔ | DX14: 46104 | DY14: 192 | DZ14: 410 | EA14: ✔ | EB14: 46111 | EC14: 192 | ED14: 400 | EE14: ✔ | EF14: 46118 | EG14: 190 | EH14: 400 | EI14: ✔ | EJ14: 46125 | EK14: 191 | EL14: 400 | EM14: ✔ | EN14: 46132 | EO14: 191 | EP14: 400 | EQ14: ✔ | ER14: 46139 | ES14: 191 | ET14: 400 | EU14: ✔ | EV14: 46146 | EW14: 191 | EX14: 400 | EY14: ✔ | EZ14: 46153 | FA14: 182 | FB14: 407.39 | FC14: ✔ | FD14: 46160 | FE14: 191 | FF14: 400 | FG14: ✔
A15: 13 | B15: ACTIVO | C15: HYUNDAI ACCENT | D15: AUTOS SEMINUEVOS 2025 - II | E15: CLH470 | F15: 230 | G15: 71108507 | H15: 931 234 955 | I15: Llacua Pariona Saul | J15: 1000 | K15: COMPLETA | L15: =IFERROR(__xludf.DUMMYFUNCTION("MAX( ARRAYFORMULA( IF( P15:ACD15<>"""", IFERROR(VALUE(REGEXEXTRACT(P$1:ACD$1,""\d+"")),0), 0 ) ) ) "),34) -> 34 | M15: =IFERROR(__xludf.DUMMYFUNCTION("COUNTIF( FILTER(T15:ACC15, REGEXMATCH(T$2:ACC$2,""Validación"")), ""❌"" ) "),6) -> 6 | N15: =SUM(R15+V15+Z15+AD15+AH15+AL15+AP15+AT15+AX15+BB15+BF15+BJ15+BN15+BR15+BV15+BZ15+CD15+CH15+CL15+CP15+CT15+CX15+DB15+DF15) -> 16481.5 | O15: =N15+(J15*3.5) -> 19981.5 | P15: 45922 | Q15: DEPÓSITO | R15: 562.5 | S15: ✔ | T15: 45929 | U15: 120 | V15: 611.27 | W15: ✔ | X15: 45936 | Y15: 186 | Z15: 420.75 | AA15: ✔ | AB15: 45943 | AC15: 111 | AD15: 607.75 | AE15: ✔ | AF15: 45950 | AG15: 111 | AH15: 668.85 | AI15: ✔ | AJ15: 45957 | AK15: 94 | AL15: 720 | AM15: ✔ | AN15: 45964 | AO15: 94 | AP15: 747.33 | AQ15: ✔ | AR15: 45971 | AS15: 146 | AT15: 680 | AU15: ✔ | AV15: 45978 | AW15: 146 | AX15: 731.25 | AY15: ✔ | AZ15: 45985 | BA15: 102 | BB15: 730.3 | BC15: ✔ | BD15: 45992 | BE15: 102 | BF15: 718.25 | BG15: ✔ | BH15: 45999 | BI15: 146 | BJ15: 729.75 | BK15: ✔ | BL15: 46006 | BM15: 121 | BN15: 731.5 | BO15: ✔ | BP15: 46013 | BQ15: 101 | BR15: 773.65 | BS15: ✔ | BT15: 46020 | BU15: 121 | BV15: 680 | BW15: ✔ | BX15: 46027 | BY15: 0 | BZ15: 731.25 | CA15: ✔ | CB15: 46034 | CC15: 50 | CD15: 699.05 | CE15: ✔ | CF15: 46041 | CG15: 101 | CH15: 680 | CI15: ✔ | CJ15: 46048 | CK15: 43 | CL15: 675 | CM15: ✔ | CN15: 46055 | CO15: 120 | CP15: 612.1 | CQ15: ✔ | CR15: 46062 | CS15: 146 | CT15: 639.2 | CU15: ✔ | CV15: 46069 | CW15: 146 | CX15: 759.4 | CY15: ✔ | CZ15: 46076 | DA15: 146 | DB15: 773.6 | DC15: ✔ | DD15: 46083 | DE15: 16 | DF15: 798.75 | DG15: ✔ | DH15: 46090 | DI15: 59 | DJ15: 850.06 | DK15: ✔ | DL15: 46097 | DM15: 121 | DN15: 731.5 | DO15: ✔ | DP15: 46104 | DQ15: 123 | DR15: 735.56 | DS15: ✔ | DT15: 46111 | DU15: 123 | DV15: 522.5 | DW15: ❌ | DX15: 46118 | DY15: 0 | DZ15: 562.5 | EA15: ❌ | EB15: 46125 | EC15: 0 | ED15: 562.5 | EE15: ❌ | EF15: 46132 | EG15: 0 | EH15: 646.23 | EI15: ✔ | EJ15: 46139 | EK15: 101 | EL15: 562.5 | EM15: ❌ | EN15: 46146 | EO15: 101 | EP15: 562.5 | EQ15: ❌ | ER15: 46153 | ES15: 72 | ET15: 562.5 | EU15: ❌
A16: 14 | B16: ACTIVO | C16: KIA SOLUTO | D16: AUTOS SEMINUEVOS 2026 - I | E16: CRM591 | F16: 183 | G16: 18091696 | H16: 959 525 249 | I16: Aspiros Lopez Andres Iduviques | J16: 1000 | K16: COMPLETA | L16: =IFERROR(__xludf.DUMMYFUNCTION("MAX( ARRAYFORMULA( IF( P16:ACD16<>"""", IFERROR(VALUE(REGEXEXTRACT(P$1:ACD$1,""\d+"")),0), 0 ) ) ) "),28) -> 28 | M16: =IFERROR(__xludf.DUMMYFUNCTION("COUNTIF( FILTER(T16:ACC16, REGEXMATCH(T$2:ACC$2,""Validación"")), ""❌"" ) "),0) -> 0 | N16: =SUM(R16+V16+Z16+AD16+AH16+AL16+AP16+AT16+AX16+BB16+BF16+BJ16+BN16+BR16+BV16+BZ16+CD16+CH16+CL16+CP16+CT16+CX16+DB16+DF16+DJ16+DN16+DR16+DV16+DZ16+ED16+EH16+EL16+EP16+ET16+EX16) -> 13483.25 | O16: =N16+(J16*3.5) -> 16983.25 | P16: 45971 | Q16: DEPÓSITO | R16: 520 | S16: ✔ | T16: 45978 | U16: 127 | V16: 480 | W16: ✔ | X16: 45985 | Y16: 129 | Z16: 480 | AA16: ✔ | AB16: 45992 | AC16: 129 | AD16: 480 | AE16: ✔ | AF16: 45999 | AG16: 132 | AH16: 480 | AI16: ✔ | AJ16: 46006 | AK16: 134 | AL16: 480 | AM16: ✔ | AN16: 46013 | AO16: 134 | AP16: 480 | AQ16: ✔ | AR16: 46020 | AS16: 121 | AT16: 480 | AU16: ✔ | AV16: 46027 | AW16: 121 | AX16: 534.86 | AY16: ✔ | AZ16: 46034 | BA16: 121 | BB16: 534.86 | BC16: ✔ | BD16: 46041 | BE16: 127 | BF16: 480 | BG16: ✔ | BH16: 46048 | BI16: 123 | BJ16: 480 | BK16: ✔ | BL16: 46055 | BM16: 101 | BN16: 516.69 | BO16: ✔ | BP16: 46062 | BQ16: 127 | BR16: 495.3 | BS16: ✔ | BT16: 46069 | BU16: 153 | BV16: 450 | BW16: ✔ | BX16: 46076 | BY16: 135 | BZ16: 480 | CA16: ✔ | CB16: 46083 | CC16: 129 | CD16: 480 | CE16: ✔ | CF16: 46090 | CG16: 156 | CH16: 450 | CI16: ✔ | CJ16: 46097 | CK16: 153 | CL16: 450 | CM16: ✔ | CN16: 46104 | CO16: 162 | CP16: 451.24 | CQ16: ✔ | CR16: 46111 | CS16: 126 | CT16: 496.12 | CU16: ✔ | CV16: 46118 | CW16: 122 | CX16: 480 | CY16: ✔ | CZ16: 46125 | DA16: 122 | DB16: 480 | DC16: ✔ | DD16: 46132 | DE16: 151 | DF16: 450 | DG16: ✔ | DH16: 46139 | DI16: 131 | DJ16: 480 | DK16: ✔ | DL16: 46146 | DM16: 120 | DN16: 484.18 | DO16: ✔ | DP16: 46153 | DQ16: 126 | DR16: 480 | DS16: ✔ | DT16: 46160 | DU16: 167 | DV16: 450 | DW16: ✔
A17: 15 | B17: ACTIVO | C17: KIA SOLUTO | D17: AUTOS SEMINUEVOS 2026 - I | E17: CRL047 | F17: 183 | G17: 9503071 | H17: 947 758 387 - 943023826 | I17: Surichaqui Lazo Johnny Julio | J17: 1000 | K17: COMPLETA | L17: =IFERROR(__xludf.DUMMYFUNCTION("MAX( ARRAYFORMULA( IF( P17:ACD17<>"""", IFERROR(VALUE(REGEXEXTRACT(P$1:ACD$1,""\d+"")),0), 0 ) ) ) "),27) -> 27 | M17: =IFERROR(__xludf.DUMMYFUNCTION("COUNTIF( FILTER(T17:ACC17, REGEXMATCH(T$2:ACC$2,""Validación"")), ""❌"" ) "),0) -> 0 | N17: =SUM(R17+V17+Z17+AD17+AH17+AL17+AP17+AT17+AX17+BB17+BF17+BJ17+BN17+BR17+BV17+BZ17+CD17+CH17) -> 9133.24 | O17: =N17+(J17*3.5) -> 12633.24 | P17: 45978 | Q17: DEPÓSITO | R17: 520 | S17: ✔ | T17: 45985 | U17: 0 | V17: 520 | W17: ✔ | X17: 45992 | Y17: 0 | Z17: 520 | AA17: ✔ | AB17: 45999 | AC17: 0 | AD17: 520 | AE17: ✔ | AF17: 46006 | AG17: 0 | AH17: 520 | AI17: ✔ | AJ17: 46013 | AK17: 0 | AL17: 520 | AM17: ✔ | AN17: 46020 | AO17: 0 | AP17: 520 | AQ17: ✔ | AR17: 46027 | AS17: 0 | AT17: 520 | AU17: ✔ | AV17: 46034 | AW17: 0 | AX17: 520 | AY17: ✔ | AZ17: 46041 | BA17: 0 | BB17: 520 | BC17: ✔ | BD17: 46048 | BE17: 180 | BF17: 420 | BG17: ✔ | BH17: 46055 | BI17: 180 | BJ17: 420 | BK17: ✔ | BL17: 46062 | BM17: 180 | BN17: 520 | BO17: ✔ | BP17: 46069 | BQ17: 0 | BR17: 519.9 | BS17: ✔ | BT17: 46076 | BU17: 149 | BV17: 543.05 | BW17: ✔ | BX17: 46083 | BY17: 146 | BZ17: 480 | CA17: ✔ | CB17: 46090 | CC17: 150 | CD17: 510.29 | CE17: ✔ | CF17: 46097 | CG17: 74 | CH17: 520 | CI17: ✔ | CJ17: 46104 | CK17: 14 | CL17: 535.51 | CM17: ✔ | CN17: 46111 | CO17: 150 | CP17: 534.73 | CQ17: ✔ | CR17: 46118 | CS17: 40 | CT17: 590.85 | CU17: ✔ | CV17: 46125 | CW17: 40 | CX17: 495 | CY17: ✔ | CZ17: 46132 | DA17: 191 | DB17: 520 | DC17: ✔ | DD17: 46139 | DE17: 152 | DF17: 428.79 | DG17: ✔ | DH17: 46146 | DI17: 152 | DJ17: 450 | DK17: ✔ | DL17: 46153 | DM17: 0 | DN17: 520 | DO17: ✔ | DP17: 46160 | DQ17: 0 | DR17: 520 | DS17: ✔
A18: 16 | B18: ACTIVO | C18: KIA SOLUTO | D18: AUTOS SEMINUEVOS 2026 - I | E18: CRM549 | F18: 183 | G18: 47635750 | H18: 928 967 692 | I18: Fonseca Coronado Gilmer | J18: 1000 | K18: COMPLETA | L18: =IFERROR(__xludf.DUMMYFUNCTION("MAX( ARRAYFORMULA( IF( P18:ACD18<>"""", IFERROR(VALUE(REGEXEXTRACT(P$1:ACD$1,""\d+"")),0), 0 ) ) ) "),25) -> 25 | M18: =IFERROR(__xludf.DUMMYFUNCTION("COUNTIF( FILTER(T18:ACC18, REGEXMATCH(T$2:ACC$2,""Validación"")), ""❌"" ) "),2) -> 2 | N18: =SUM(R18+V18+Z18+AD18+AH18+AL18+AP18+AT18+AX18+BB18+BF18+BJ18+BN18+BR18+BV18+BZ18) -> 8134.84 | O18: =N18+(J18*3.5) -> 11634.84 | P18: 45992 | Q18: DEPÓSITO | R18: 520 | S18: ✔ | T18: 45999 | U18: 0 | V18: 520 | W18: ✔ | X18: 46006 | Y18: 0 | Z18: 520 | AA18: ✔ | AB18: 46013 | AC18: 105 | AD18: 510 | AE18: ✔ | AF18: 46020 | AG18: 145 | AH18: 480 | AI18: ✔ | AJ18: 46027 | AK18: 120 | AL18: 480 | AM18: ✔ | AN18: 46034 | AO18: 121 | AP18: 485 | AQ18: ✔ | AR18: 46041 | AS18: 107 | AT18: 534 | AU18: ✔ | AV18: 46048 | AW18: 121 | AX18: 480 | AY18: ✔ | AZ18: 46055 | BA18: 145 | BB18: 490 | BC18: ✔ | BD18: 46062 | BE18: 145 | BF18: 480 | BG18: ✔ | BH18: 46069 | BI18: 30 | BJ18: 568.62 | BK18: ✔ | BL18: 46076 | BM18: 151 | BN18: 480 | BO18: ✔ | BP18: 46083 | BQ18: 150 | BR18: 547.22 | BS18: ✔ | BT18: 46090 | BU18: 71 | BV18: 520 | BW18: ✔ | BX18: 46097 | BY18: 39 | BZ18: 520 | CA18: ✔ | CB18: 46104 | CC18: 47 | CD18: 624 | CE18: ✔ | CF18: 46111 | CG18: 45 | CH18: 520 | CI18: ✔ | CJ18: 46118 | CK18: 4 | CL18: 572 | CM18: ✔ | CN18: 46125 | CO18: 0 | CP18: 572 | CQ18: ✔ | CR18: 46132 | CS18: 37 | CT18: 572 | CU18: ✔ | CV18: 46139 | CW18: 37 | CX18: 628.87 | CY18: ✔ | CZ18: 46146 | DA18: 34 | DB18: 659.61 | DC18: ✔ | DD18: 46153 | DE18: 34 | DF18: 300.8 | DG18: ❌ | DH18: 46160 | DI18: 100 | DJ18: 520 | DK18: ❌
A19: 17 | B19: ACTIVO | C19: HYUNDAI ACCENT | D19: AUTOS SEMINUEVOS 2026 - I | E19: CLH665 | F19: 210 | G19: 46850186 | H19: 987626081 - 937356543 | I19: Quispe Ñahuincopa Emerson | J19: 1000 | K19: COMPLETA | L19: =IFERROR(__xludf.DUMMYFUNCTION("MAX( ARRAYFORMULA( IF( P19:ACD19<>"""", IFERROR(VALUE(REGEXEXTRACT(P$1:ACD$1,""\d+"")),0), 0 ) ) ) "),13) -> 13 | M19: =IFERROR(__xludf.DUMMYFUNCTION("COUNTIF( FILTER(T19:ACC19, REGEXMATCH(T$2:ACC$2,""Validación"")), ""❌"" ) "),2) -> 2 | N19: =SUM(R19+V19+Z19) -> 1724.57 | O19: =N19+(J19*3.5) -> 5224.57 | P19: 46076 | Q19: DEPÓSITO | R19: 520 | S19: ✔ | T19: 46083 | U19: 101 | V19: 575.37 | W19: ✔ | X19: 46090 | Y19: 47 | Z19: 629.2 | AA19: ✔ | AB19: 46097 | AC19: 55 | AD19: 686.24 | AE19: ✔ | AF19: 46104 | AG19: 135 | AH19: 624 | AI19: ✔ | AJ19: 46111 | AK19: 120 | AL19: 669.27 | AM19: ✔ | AN19: 46118 | AO19: 96 | AP19: 520 | AQ19: ✔ | AR19: 46125 | AS19: 96 | AT19: 520 | AU19: ✔ | AV19: 46132 | AW19: 77 | AX19: 624 | AY19: ✔ | AZ19: 46139 | BA19: 100 | BB19: 654.5 | BC19: ✔ | BD19: 46146 | BE19: 100 | BF19: 623.96 | BG19: ✔ | BH19: 46153 | BI19: 99 | BJ19: 520 | BK19: ❌ | BL19: 46160 | BM19: 100 | BN19: 520 | BO19: ❌
A20: 18 | B20: ACTIVO | C20: KIA SOLUTO - 0KM | D20: AUTOS 0KM 2026 - I | E20: CWP640 | F20: 261 | G20: 003800663 | H20: 904013996 | I20: Hassan Vargas Hendrik Hawasma | J20: 1000 | K20: COMPLETA | L20: =IFERROR(__xludf.DUMMYFUNCTION("MAX( ARRAYFORMULA( IF( P20:ACD20<>"""", IFERROR(VALUE(REGEXEXTRACT(P$1:ACD$1,""\d+"")),0), 0 ) ) ) "),12) -> 12 | M20: =IFERROR(__xludf.DUMMYFUNCTION("COUNTIF( FILTER(T20:ACC20, REGEXMATCH(T$2:ACC$2,""Validación"")), ""❌"" ) "),0) -> 0 | N20: =SUM(R20+V20+Z20+AD20+AH20+AL20+AP20+AT20+AX20+BB20+BF20+BJ20+BN20+BR20+BV20+BZ20+CD20+CH20+CL20+CP20+CT20+CX20+DB20+DF20+DJ20+DN20+DR20+DV20+DZ20+ED20+EH20+EL20+EP20+ET20+EX20) -> 5430 | O20: =N20+(J20*3.45) -> 8880 | P20: 46083 | Q20: DEPÓSITO | R20: 480 | S20: ✔ | T20: 46090 | U20: 111 | V20: 480 | W20: ✔ | X20: 46097 | Y20: 121 | Z20: 460 | AA20: ✔ | AB20: 46104 | AC20: 122 | AD20: 460 | AE20: ✔ | AF20: 46111 | AG20: 128 | AH20: 460 | AI20: ✔ | AJ20: 46118 | AK20: 153 | AL20: 430 | AM20: ✔ | AN20: 46125 | AO20: 153 | AP20: 430 | AQ20: ✔ | AR20: 46132 | AS20: 127 | AT20: 460 | AU20: ✔ | AV20: 46139 | AW20: 151 | AX20: 430 | AY20: ✔ | AZ20: 46146 | BA20: 152 | BB20: 430 | BC20: ✔ | BD20: 46153 | BE20: 152 | BF20: 430 | BG20: ✔ | BH20: 46160 | BI20: 152 | BJ20: 480 | BK20: ✔
A21: 19 | B21: ACTIVO | C21: KIA SOLUTO - 0KM | D21: AUTOS 0KM 2026 - I | E21: CWR264 | F21: 261 | G21: 47382328 | H21: 933785255 | I21: Ortiz Lagos Luis Enrique | J21: 500 | K21: PARCIAL | L21: =IFERROR(__xludf.DUMMYFUNCTION("MAX( ARRAYFORMULA( IF( P21:ACD21<>"""", IFERROR(VALUE(REGEXEXTRACT(P$1:ACD$1,""\d+"")),0), 0 ) ) ) "),11) -> 11 | M21: =IFERROR(__xludf.DUMMYFUNCTION("COUNTIF( FILTER(T21:ACC21, REGEXMATCH(T$2:ACC$2,""Validación"")), ""❌"" ) "),0) -> 0 | N21: =SUM(R21+V21+Z21+AD21+AH21+AL21+AP21+AT21+AX21+BB21+BF21+BJ21+BN21+BR21+BV21+BZ21+CD21+CH21+CL21+CP21+CT21+CX21+DB21+DF21+DJ21+DN21+DR21+DV21+DZ21+ED21+EH21+EL21+EP21+ET21+EX21) -> 5017.08 | O21: =N21+(J21*3.45) -> 6742.08 | P21: 46090 | Q21: DEPÓSITO | R21: 480 | S21: ✔ | T21: 46097 | U21: 121 | V21: 460 | W21: ✔ | X21: 46104 | Y21: 154 | Z21: 430 | AA21: ✔ | AB21: 46111 | AC21: 151 | AD21: 430 | AE21: ✔ | AF21: 46118 | AG21: 150 | AH21: 430 | AI21: ✔ | AJ21: 46125 | AK21: 100 | AL21: 430 | AM21: ✔ | AN21: 46132 | AO21: 150 | AP21: 430 | AQ21: ✔ | AR21: 46139 | AS21: 52 | AT21: 480 | AU21: ✔ | AV21: 46146 | AW21: 19 | AX21: 480 | AY21: ✔ | AZ21: 46153 | BA21: 50 | BB21: 487.08 | BC21: ✔ | BD21: 46160 | BE21: 49 | BF21: 480 | BG21: ✔
A22: 22 | B22: ACTIVO | C22: KIA SOLUTO - 0KM | D22: AUTOS 0KM 2026 - I | E22: CWP642 | F22: 261 | G22: 41449391 | H22: 984435470 | I22: Picoy Aguirre Einstein Yury | J22: 1000 | K22: COMPLETA | L22: =IFERROR(__xludf.DUMMYFUNCTION("MAX( ARRAYFORMULA( IF( P22:ACD22<>"""", IFERROR(VALUE(REGEXEXTRACT(P$1:ACD$1,""\d+"")),0), 0 ) ) ) "),10) -> 10 | M22: =IFERROR(__xludf.DUMMYFUNCTION("COUNTIF( FILTER(T22:ACC22, REGEXMATCH(T$2:ACC$2,""Validación"")), ""❌"" ) "),1) -> 1 | N22: =SUM(R22+V22+Z22+AD22+AH22+AL22+AP22+AT22+AX22+BB22+BF22+BJ22+BN22+BR22+BV22+BZ22+CD22+CH22+CL22+CP22+CT22+CX22+DB22+DF22+DJ22+DN22+DR22+DV22+DZ22+ED22+EH22+EL22+EP22+ET22+EX22) -> 4531 | O22: =N22+(J22*3.45) -> 7981 | P22: 46098 | Q22: DEPÓSITO | R22: 480 | S22: ✔ | T22: 46104 | U22: 112 | V22: 480.02 | W22: ✔ | X22: 46111 | Y22: 121 | Z22: 460 | AA22: ✔ | AB22: 46118 | AC22: 121 | AD22: 460 | AE22: ✔ | AF22: 46125 | AG22: 100 | AH22: 480 | AI22: ✔ | AJ22: 46132 | AK22: 47 | AL22: 495.57 | AM22: ✔ | AN22: 46139 | AO22: 0 | AP22: 499.5 | AQ22: ✔ | AR22: 46146 | AS22: 125 | AT22: 479.3 | AU22: ✔ | AV22: 46153 | AW22: 154 | AX22: 473 | AY22: ✔ | AZ22: 46160 | BA22: 127 | BB22: 223.61 | BC22: ❌
A23: 20 | B23: ACTIVO | C23: KIA SOLUTO - 0KM | D23: AUTOS 0KM 2026 - I | E23: CWP311 | F23: 261 | G23: 08296738 | H23: 976385733 | I23: Davila Alvitres Felipe Basilio | J23: 500 | K23: PARCIAL | L23: =IFERROR(__xludf.DUMMYFUNCTION("MAX( ARRAYFORMULA( IF( P23:ACD23<>"""", IFERROR(VALUE(REGEXEXTRACT(P$1:ACD$1,""\d+"")),0), 0 ) ) ) "),10) -> 10 | M23: =IFERROR(__xludf.DUMMYFUNCTION("COUNTIF( FILTER(T23:ACC23, REGEXMATCH(T$2:ACC$2,""Validación"")), ""❌"" ) "),0) -> 0 | N23: =SUM(R23+V23+Z23+AD23+AH23+AL23+AP23+AT23+AX23+BB23+BF23+BJ23+BN23+BR23+BV23+BZ23+CD23+CH23+CL23+CP23+CT23+CX23+DB23+DF23+DJ23+DN23+DR23+DV23+DZ23+ED23+EH23+EL23+EP23+ET23+EX23) -> 4542 | O23: =N23+(J23*3.45) -> 6267 | P23: 46097 | Q23: DEPÓSITO | R23: 480 | S23: ✔ | T23: 46104 | U23: 158 | V23: 482 | W23: ✔ | X23: 46111 | Y23: 153 | Z23: 430 | AA23: ✔ | AB23: 46118 | AC23: 123 | AD23: 460 | AE23: ✔ | AF23: 46125 | AG23: 123 | AH23: 460 | AI23: ✔ | AJ23: 46132 | AK23: 150 | AL23: 430 | AM23: ✔ | AN23: 46139 | AO23: 70 | AP23: 480 | AQ23: ✔ | AR23: 46146 | AS23: 126 | AT23: 460 | AU23: ✔ | AV23: 46153 | AW23: 150 | AX23: 430 | AY23: ✔ | AZ23: 46160 | BA23: 150 | BB23: 430 | BC23: ✔
A24: 21 | B24: ACTIVO | C24: KIA SOLUTO - 0KM | D24: AUTOS 0KM 2026 - I | E24: CWO243 | F24: 261 | G24: 007843417 | H24: 917611185 | I24: Flores Ulloa Wilmer alfonso | J24: 500 | K24: PARCIAL | L24: =IFERROR(__xludf.DUMMYFUNCTION("MAX( ARRAYFORMULA( IF( P24:ACD24<>"""", IFERROR(VALUE(REGEXEXTRACT(P$1:ACD$1,""\d+"")),0), 0 ) ) ) "),10) -> 10 | M24: =IFERROR(__xludf.DUMMYFUNCTION("COUNTIF( FILTER(T24:ACC24, REGEXMATCH(T$2:ACC$2,""Validación"")), ""❌"" ) "),0) -> 0 | N24: =SUM(R24+V24+Z24+AD24+AH24+AL24+AP24+AT24+AX24+BB24+BF24+BJ24+BN24+BR24+BV24+BZ24+CD24+CH24+CL24+CP24+CT24+CX24+DB24+DF24+DJ24+DN24+DR24+DV24+DZ24+ED24+EH24+EL24+EP24+ET24+EX24) -> 4620 | O24: =N24+(J24*3.45) -> 6345 | P24: 46098 | Q24: DEPÓSITO | R24: 480 | S24: ✔ | T24: 46104 | U24: 124 | V24: 460 | W24: ✔ | X24: 46111 | Y24: 120 | Z24: 460 | AA24: ✔ | AB24: 46118 | AC24: 121 | AD24: 460 | AE24: ✔ | AF24: 46125 | AG24: 121 | AH24: 460 | AI24: ✔ | AJ24: 46132 | AK24: 121 | AL24: 460 | AM24: ✔ | AN24: 46139 | AO24: 125 | AP24: 460 | AQ24: ✔ | AR24: 46146 | AS24: 128 | AT24: 460 | AU24: ✔ | AV24: 46153 | AW24: 126 | AX24: 460 | AY24: ✔ | AZ24: 46160 | BA24: 126 | BB24: 460 | BC24: ✔
A25: 23 | B25: ACTIVO | C25: KIA SOLUTO - 0KM | D25: AUTOS 0KM 2026 - I | E25: CWO147 | F25: 261 | G25: 08872540 | H25: 969654289 | I25: Rodriguez Martinez Jose Luis | J25: 500 | K25: PARCIAL | L25: =IFERROR(__xludf.DUMMYFUNCTION("MAX( ARRAYFORMULA( IF( P25:ACD25<>"""", IFERROR(VALUE(REGEXEXTRACT(P$1:ACD$1,""\d+"")),0), 0 ) ) ) "),10) -> 10 | M25: =IFERROR(__xludf.DUMMYFUNCTION("COUNTIF( FILTER(T25:ACC25, REGEXMATCH(T$2:ACC$2,""Validación"")), ""❌"" ) "),0) -> 0 | N25: =SUM(R25+V25+Z25+AD25+AH25+AL25+AP25+AT25+AX25+BB25+BF25+BJ25+BN25+BR25+BV25+BZ25+CD25+CH25+CL25+CP25+CT25+CX25+DB25+DF25+DJ25+DN25+DR25+DV25+DZ25+ED25+EH25+EL25+EP25+ET25+EX25) -> 4380 | O25: =N25+(J25*3.45) -> 6105 | P25: 46098 | Q25: DEPÓSITO | R25: 480 | S25: ✔ | T25: 46104 | U25: 121 | V25: 460 | W25: ✔ | X25: 46111 | Y25: 153 | Z25: 430 | AA25: ✔ | AB25: 46118 | AC25: 153 | AD25: 430 | AE25: ✔ | AF25: 46125 | AG25: 153 | AH25: 430 | AI25: ✔ | AJ25: 46132 | AK25: 152 | AL25: 430 | AM25: ✔ | AN25: 46139 | AO25: 152 | AP25: 430 | AQ25: ✔ | AR25: 46146 | AS25: 152 | AT25: 430 | AU25: ✔ | AV25: 46153 | AW25: 154 | AX25: 430 | AY25: ✔ | AZ25: 46160 | BA25: 151 | BB25: 430 | BC25: ✔
A26: 24 | B26: ACTIVO | C26: KIA SOLUTO - 0KM | D26: AUTOS 0KM 2026 - I | E26: CWQ370 | F26: 261 | G26: 42131968 | H26: 942640722 | I26: Salguero yrribari Felipe Eduardo | J26: 500 | K26: PARCIAL | L26: =IFERROR(__xludf.DUMMYFUNCTION("MAX( ARRAYFORMULA( IF( P26:ACD26<>"""", IFERROR(VALUE(REGEXEXTRACT(P$1:ACD$1,""\d+"")),0), 0 ) ) ) "),10) -> 10 | M26: =IFERROR(__xludf.DUMMYFUNCTION("COUNTIF( FILTER(T26:ACC26, REGEXMATCH(T$2:ACC$2,""Validación"")), ""❌"" ) "),1) -> 1 | N26: =SUM(R26+Z26+AD26+AH26+AL26+AP26+AT26+AX26+BB26+BF26+BJ26+BN26+BR26+BV26+BZ26+CD26+CH26+CL26+CP26+CT26+CX26+DB26+DF26+DJ26+DN26+DR26+DV26+DZ26+ED26+EH26+EL26+EP26+ET26+EX26) -> 4089.81 | O26: =N26+(J26*3.45) -> 5814.81 | P26: 46098 | Q26: DEPÓSITO | R26: 480 | S26: ✔ | T26: 46104 | U26: 0 | V26: 499.2 | W26: ✔ | X26: 46111 | Y26: 44 | Z26: 485.35 | AA26: ✔ | AB26: 46118 | AC26: 100 | AD26: 480 | AE26: ✔ | AF26: 46125 | AG26: 100 | AH26: 542.09 | AI26: ✔ | AJ26: 46132 | AK26: 75 | AL26: 499.2 | AM26: ✔ | AN26: 46139 | AO26: 55 | AP26: 506.47 | AQ26: ✔ | AR26: 46146 | AS26: 95 | AT26: 88.7 | AU26: ❌ | AV26: 46153 | AW26: 106 | AX26: 528 | AY26: ✔ | AZ26: 46160 | BA26: 80 | BB26: 480 | BC26: ✔
A27: 25 | B27: ACTIVO | C27: KIA SOLUTO - 0KM | D27: AUTOS 0KM 2026 - I | E27: CWO329 | F27: 261 | G27: 42145889 | H27: 956711269 | I27: García Rubio John Eugenio | J27: 500 | K27: PARCIAL | L27: =IFERROR(__xludf.DUMMYFUNCTION("MAX( ARRAYFORMULA( IF( P27:ACD27<>"""", IFERROR(VALUE(REGEXEXTRACT(P$1:ACD$1,""\d+"")),0), 0 ) ) ) "),9) -> 9 | M27: =IFERROR(__xludf.DUMMYFUNCTION("COUNTIF( FILTER(T27:ACC27, REGEXMATCH(T$2:ACC$2,""Validación"")), ""❌"" ) "),1) -> 1 | N27: =SUM(R27+V27+Z27+AD27+AH27+AL27+AP27+AT27+AX27+BB27+BF27+BJ27+BN27+BR27+BV27+BZ27+CD27+CH27+CL27+CP27+CT27+CX27+DB27+DF27+DJ27+DN27+DR27+DV27+DZ27+ED27+EH27+EL27+EP27+ET27+EX27) -> 4313.79 | O27: =N27+(J27*3.47) -> 6048.79 | P27: 46104 | Q27: DEPÓSITO | R27: 480 | S27: ✔ | T27: 46111 | U27: 55 | V27: 480 | W27: ✔ | X27: 46118 | Y27: 120 | Z27: 480 | AA27: ✔ | AB27: 46125 | AC27: 120 | AD27: 480 | AE27: ✔ | AF27: 46132 | AG27: 101 | AH27: 480 | AI27: ✔ | AJ27: 46139 | AK27: 102 | AL27: 480 | AM27: ✔ | AN27: 46146 | AO27: 125 | AP27: 460 | AQ27: ✔ | AR27: 46153 | AS27: 61 | AT27: 493.79 | AU27: ✔ | AV27: 46160 | AW27: 62 | AX27: 480 | AY27: ❌
A28: 26 | B28: ACTIVO | C28: KIA SOLUTO - 0KM | D28: AUTOS 0KM 2026 - I | E28: CWR451 | F28: 261 | G28: 10810482 | H28: 974510445 | I28: Lujan Contreras Charles | J28: 500 | K28: PARCIAL | L28: =IFERROR(__xludf.DUMMYFUNCTION("MAX( ARRAYFORMULA( IF( P28:ACD28<>"""", IFERROR(VALUE(REGEXEXTRACT(P$1:ACD$1,""\d+"")),0), 0 ) ) ) "),9) -> 9 | M28: =IFERROR(__xludf.DUMMYFUNCTION("COUNTIF( FILTER(T28:ACC28, REGEXMATCH(T$2:ACC$2,""Validación"")), ""❌"" ) "),0) -> 0 | N28: =SUM(R28+V28+Z28+AD28+AH28+AL28+AP28+AT28+AX28+BB28+BF28+BJ28+BN28+BR28+BV28+BZ28+CD28+CH28+CL28+CP28+CT28+CX28+DB28+DF28+DJ28+DN28+DR28+DV28+DZ28+ED28+EH28+EL28+EP28+ET28+EX28) -> 4180 | O28: =N28+(J28*3.47) -> 5915 | P28: 46104 | Q28: DEPÓSITO | R28: 480 | S28: ✔ | T28: 46111 | U28: 95 | V28: 480 | W28: ✔ | X28: 46118 | Y28: 120 | Z28: 460 | AA28: ✔ | AB28: 46125 | AC28: 120 | AD28: 460 | AE28: ✔ | AF28: 46132 | AG28: 126 | AH28: 460 | AI28: ✔ | AJ28: 46139 | AK28: 125 | AL28: 460 | AM28: ✔ | AN28: 46146 | AO28: 125 | AP28: 460 | AQ28: ✔ | AR28: 46153 | AS28: 125 | AT28: 460 | AU28: ✔ | AV28: 46160 | AW28: 125 | AX28: 460 | AY28: ✔
A29: 27 | B29: ACTIVO | C29: KIA SOLUTO - 0KM | D29: AUTOS 0KM 2026 - I | E29: CWP309 | F29: 261 | G29: 09842683 | H29: 945642925 | I29: Orihuela Pariona Jose Joaquin | J29: 500 | K29: PARCIAL | L29: =IFERROR(__xludf.DUMMYFUNCTION("MAX( ARRAYFORMULA( IF( P29:ACD29<>"""", IFERROR(VALUE(REGEXEXTRACT(P$1:ACD$1,""\d+"")),0), 0 ) ) ) "),9) -> 9 | M29: =IFERROR(__xludf.DUMMYFUNCTION("COUNTIF( FILTER(T29:ACC29, REGEXMATCH(T$2:ACC$2,""Validación"")), ""❌"" ) "),0) -> 0 | N29: =SUM(R29+V29+Z29+AD29+AH29+AL29+AP29+AT29+AX29+BB29+BF29+BJ29+BN29+BR29+BV29+BZ29+CD29+CH29+CL29+CP29+CT29+CX29+DB29+DF29+DJ29+DN29+DR29+DV29+DZ29+ED29+EH29+EL29+EP29+ET29+EX29) -> 3920 | O29: =N29+(J29*3.47) -> 5655 | P29: 46104 | Q29: DEPÓSITO | R29: 480 | S29: ✔ | T29: 46111 | U29: 151 | V29: 430 | W29: ✔ | X29: 46118 | Y29: 151 | Z29: 430 | AA29: ✔ | AB29: 46125 | AC29: 151 | AD29: 430 | AE29: ✔ | AF29: 46132 | AG29: 151 | AH29: 430 | AI29: ✔ | AJ29: 46139 | AK29: 151 | AL29: 430 | AM29: ✔ | AN29: 46146 | AO29: 150 | AP29: 430 | AQ29: ✔ | AR29: 46153 | AS29: 150 | AT29: 430 | AU29: ✔ | AV29: 46160 | AW29: 150 | AX29: 430 | AY29: ✔
A30: 28 | B30: ACTIVO | C30: KIA SOLUTO - 0KM | D30: AUTOS 0KM 2026 - I | E30: CWP641 | F30: 261 | G30: 42805249 | H30: 942742803 | I30: Portocarrero Giovani | J30: 500 | K30: PARCIAL | L30: =IFERROR(__xludf.DUMMYFUNCTION("MAX( ARRAYFORMULA( IF( P30:ACD30<>"""", IFERROR(VALUE(REGEXEXTRACT(P$1:ACD$1,""\d+"")),0), 0 ) ) ) "),9) -> 9 | M30: =IFERROR(__xludf.DUMMYFUNCTION("COUNTIF( FILTER(T30:ACC30, REGEXMATCH(T$2:ACC$2,""Validación"")), ""❌"" ) "),2) -> 2 | N30: =SUM(R30+V30+Z30+AD30+AH30+AL30+AP30+AT30+AX30+BB30+BF30+BJ30+BN30+BR30+BV30+BZ30+CD30+CH30+CL30+CP30+CT30+CX30+DB30+DF30+DJ30+DN30+DR30+DV30+DZ30+ED30+EH30+EL30+EP30+ET30+EX30) -> 4209.41 | O30: =N30+(J30*3.47) -> 5944.41 | P30: 46104 | Q30: DEPÓSITO | R30: 480 | S30: ✔ | T30: 46111 | U30: 95 | V30: 480 | W30: ✔ | X30: 46118 | Y30: 76 | Z30: 507.63 | AA30: ✔ | AB30: 46125 | AC30: 0 | AD30: 488.23 | AE30: ✔ | AF30: 46132 | AG30: 104 | AH30: 494.25 | AI30: ✔ | AJ30: 46139 | AK30: 100 | AL30: 499.2 | AM30: ✔ | AN30: 46146 | AO30: 120 | AP30: 503.95 | AQ30: ✔ | AR30: 46153 | AS30: 42 | AT30: 276.15 | AU30: ❌ | AV30: 46160 | AW30: 96 | AX30: 480 | AY30: ❌
A31: 29 | B31: ACTIVO | C31: KIA SOLUTO - 0KM | D31: AUTOS 0KM 2026 - I | E31: CWO330 | F31: 261 | G31: 46898799 | H31: 978327431 | I31: Ramos Rivera Deyvi Steven | J31: 500 | K31: PARCIAL | L31: =IFERROR(__xludf.DUMMYFUNCTION("MAX( ARRAYFORMULA( IF( P31:ACD31<>"""", IFERROR(VALUE(REGEXEXTRACT(P$1:ACD$1,""\d+"")),0), 0 ) ) ) "),9) -> 9 | M31: =IFERROR(__xludf.DUMMYFUNCTION("COUNTIF( FILTER(T31:ACC31, REGEXMATCH(T$2:ACC$2,""Validación"")), ""❌"" ) "),0) -> 0 | N31: =SUM(R31+V31+Z31+AD31+AH31+AL31+AP31+AT31+AX31+BB31+BF31+BJ31+BN31+BR31+BV31+BZ31+CD31+CH31+CL31+CP31+CT31+CX31+DB31+DF31+DJ31+DN31+DR31+DV31+DZ31+ED31+EH31+EL31+EP31+ET31+EX31) -> 4060 | O31: =N31+(J31*3.47) -> 5795 | P31: 46104 | Q31: DEPÓSITO | R31: 480 | S31: ✔ | T31: 46111 | U31: 66 | V31: 480 | W31: ✔ | X31: 46118 | Y31: 150 | Z31: 430 | AA31: ✔ | AB31: 46125 | AC31: 150 | AD31: 430 | AE31: ✔ | AF31: 46132 | AG31: 125 | AH31: 460 | AI31: ✔ | AJ31: 46139 | AK31: 125 | AL31: 460 | AM31: ✔ | AN31: 46146 | AO31: 128 | AP31: 460 | AQ31: ✔ | AR31: 46153 | AS31: 150 | AT31: 430 | AU31: ✔ | AV31: 46160 | AW31: 151 | AX31: 430 | AY31: ✔
